Workbook
Name _1억원: '[1]Master sheet'!$AH$13
Name _2019PAX: '[1]Master sheet'!$M$16
Name USDKRW: '[1]Master sheet'!$AH$12
Name WATD_2021: [2]!Table23[[#All],[IATA Code]:[Total cargo 2019]]
Name WATD_2023: '[2]WATD 2022'!$I$2:$AM$2679
Name WATD2019: [2]!Table24[[#All],[IATA Code]:[Total cargo 2017]]

Sheet Pax Demand
A1: top | B1: mid | C1: low | D1: decimal | E1: changeable | F1: 변수설명 | G1: Ref_Index | H1: =I1-1 | I1: =J1-1 | J1: =K1-1 | K1: =L1-1 | L1: =M1-1 | M1: =N1-1 | N1: =O1-1 | O1: =P1-1 | P1: =Q1-1 | Q1: =ref!B4 | R1: =Q1+1 | S1: =R1+1 | T1: =S1+1 | U1: =T1+1 | V1: =U1+1 | W1: =V1+1 | X1: =W1+1 | Y1: =X1+1 | ... BA1: =AZ1+1
A2: General Index | B2: Passenger Index | C2: Annual Passengers📝 | D2: float0 | E2: O | F2: 연간여객 | H2: =VLOOKUP($F2,raw_data_pax!$1:$1048576,MATCH(H$1,raw_data_pax!$1:$1,0),FALSE) | I2: =VLOOKUP($F2,raw_data_pax!$1:$1048576,MATCH(I$1,raw_data_pax!$1:$1,0),FALSE) | J2: =VLOOKUP($F2,raw_data_pax!$1:$1048576,MATCH(J$1,raw_data_pax!$1:$1,0),FALSE) | K2: =VLOOKUP($F2,raw_data_pax!$1:$1048576,MATCH(K$1,raw_data_pax!$1:$1,0),FALSE) | L2: =VLOOKUP($F2,raw_data_pax!$1:$1048576,MATCH(L$1,raw_data_pax!$1:$1,0),FALSE) | M2: =VLOOKUP($F2,raw_data_pax!$1:$1048576,MATCH(M$1,raw_data_pax!$1:$1,0),FALSE) | N2: =VLOOKUP($F2,raw_data_pax!$1:$1048576,MATCH(N$1,raw_data_pax!$1:$1,0),FALSE) | O2: =VLOOKUP($F2,raw_data_pax!$1:$1048576,MATCH(O$1,raw_data_pax!$1:$1,0),FALSE) | ... Q2: =VLOOKUP($F2,raw_data_pax!$1:$1048576,MATCH(Q$1,raw_data_pax!$1:$1,0),FALSE) | R2: =HLOOKUP(R1,'Final (total_pax)'!$1:$4,4,FALSE) | S2: =HLOOKUP(S1,'Final (total_pax)'!$1:$4,4,FALSE) | T2: =HLOOKUP(T1,'Final (total_pax)'!$1:$4,4,FALSE) | U2: =HLOOKUP(U1,'Final (total_pax)'!$1:$4,4,FALSE) | V2: =HLOOKUP(V1,'Final (total_pax)'!$1:$4,4,FALSE) | W2: =HLOOKUP(W1,'Final (total_pax)'!$1:$4,4,FALSE) | X2: =HLOOKUP(X1,'Final (total_pax)'!$1:$4,4,FALSE) | Y2: =HLOOKUP(Y1,'Final (total_pax)'!$1:$4,4,FALSE) | ... BA2: =HLOOKUP(BA1,'Final (total_pax)'!$1:$4,4,FALSE)
C3: International Passengers | D3: float0 | F3: International여객 | H3: =VLOOKUP($F3,raw_data_pax!$1:$1048576,MATCH(H$1,raw_data_pax!$1:$1,0),FALSE) | I3: =VLOOKUP($F3,raw_data_pax!$1:$1048576,MATCH(I$1,raw_data_pax!$1:$1,0),FALSE) | J3: =VLOOKUP($F3,raw_data_pax!$1:$1048576,MATCH(J$1,raw_data_pax!$1:$1,0),FALSE) | K3: =VLOOKUP($F3,raw_data_pax!$1:$1048576,MATCH(K$1,raw_data_pax!$1:$1,0),FALSE) | L3: =VLOOKUP($F3,raw_data_pax!$1:$1048576,MATCH(L$1,raw_data_pax!$1:$1,0),FALSE) | M3: =VLOOKUP($F3,raw_data_pax!$1:$1048576,MATCH(M$1,raw_data_pax!$1:$1,0),FALSE) | N3: =VLOOKUP($F3,raw_data_pax!$1:$1048576,MATCH(N$1,raw_data_pax!$1:$1,0),FALSE) | O3: =VLOOKUP($F3,raw_data_pax!$1:$1048576,MATCH(O$1,raw_data_pax!$1:$1,0),FALSE) | ... Q3: =VLOOKUP($F3,raw_data_pax!$1:$1048576,MATCH(Q$1,raw_data_pax!$1:$1,0),FALSE) | R3: =R2*R9 | S3: =S2*S9 | T3: =T2*T9 | U3: =U2*U9 | V3: =V2*V9 | W3: =W2*W9 | X3: =X2*X9 | Y3: =Y2*Y9 | ... BA3: =BA2*BA9
C4: Domestic Passengers | D4: float0 | F4: Domestic여객 | H4: =VLOOKUP($F4,raw_data_pax!$1:$1048576,MATCH(H$1,raw_data_pax!$1:$1,0),FALSE) | I4: =VLOOKUP($F4,raw_data_pax!$1:$1048576,MATCH(I$1,raw_data_pax!$1:$1,0),FALSE) | J4: =VLOOKUP($F4,raw_data_pax!$1:$1048576,MATCH(J$1,raw_data_pax!$1:$1,0),FALSE) | K4: =VLOOKUP($F4,raw_data_pax!$1:$1048576,MATCH(K$1,raw_data_pax!$1:$1,0),FALSE) | L4: =VLOOKUP($F4,raw_data_pax!$1:$1048576,MATCH(L$1,raw_data_pax!$1:$1,0),FALSE) | M4: =VLOOKUP($F4,raw_data_pax!$1:$1048576,MATCH(M$1,raw_data_pax!$1:$1,0),FALSE) | N4: =VLOOKUP($F4,raw_data_pax!$1:$1048576,MATCH(N$1,raw_data_pax!$1:$1,0),FALSE) | O4: =VLOOKUP($F4,raw_data_pax!$1:$1048576,MATCH(O$1,raw_data_pax!$1:$1,0),FALSE) | ... Q4: =VLOOKUP($F4,raw_data_pax!$1:$1048576,MATCH(Q$1,raw_data_pax!$1:$1,0),FALSE) | R4: =R2-R3 | S4: =S2-S3 | T4: =T2-T3 | U4: =U2-U3 | V4: =V2-V3 | W4: =W2-W3 | X4: =X2-X3 | Y4: =Y2-Y3 | ... BA4: =BA2-BA3
C5: Long_haul Passengers | D5: float0 | F5: Long_haul여객 | H5: =VLOOKUP($F5,raw_data_pax!$1:$1048576,MATCH(H$1,raw_data_pax!$1:$1,0),FALSE) | I5: =VLOOKUP($F5,raw_data_pax!$1:$1048576,MATCH(I$1,raw_data_pax!$1:$1,0),FALSE) | J5: =VLOOKUP($F5,raw_data_pax!$1:$1048576,MATCH(J$1,raw_data_pax!$1:$1,0),FALSE) | K5: =VLOOKUP($F5,raw_data_pax!$1:$1048576,MATCH(K$1,raw_data_pax!$1:$1,0),FALSE) | L5: =VLOOKUP($F5,raw_data_pax!$1:$1048576,MATCH(L$1,raw_data_pax!$1:$1,0),FALSE) | M5: =VLOOKUP($F5,raw_data_pax!$1:$1048576,MATCH(M$1,raw_data_pax!$1:$1,0),FALSE) | N5: =VLOOKUP($F5,raw_data_pax!$1:$1048576,MATCH(N$1,raw_data_pax!$1:$1,0),FALSE) | O5: =VLOOKUP($F5,raw_data_pax!$1:$1048576,MATCH(O$1,raw_data_pax!$1:$1,0),FALSE) | ... Q5: =VLOOKUP($F5,raw_data_pax!$1:$1048576,MATCH(Q$1,raw_data_pax!$1:$1,0),FALSE) | R5: =R2*R10 | S5: =S2*S10 | T5: =T2*T10 | U5: =U2*U10 | V5: =V2*V10 | W5: =W2*W10 | X5: =X2*X10 | Y5: =Y2*Y10 | ... BA5: =BA2*BA10
C6: Short_haul Passengers | D6: float0 | F6: Short_haul여객 | H6: =VLOOKUP($F6,raw_data_pax!$1:$1048576,MATCH(H$1,raw_data_pax!$1:$1,0),FALSE) | I6: =VLOOKUP($F6,raw_data_pax!$1:$1048576,MATCH(I$1,raw_data_pax!$1:$1,0),FALSE) | J6: =VLOOKUP($F6,raw_data_pax!$1:$1048576,MATCH(J$1,raw_data_pax!$1:$1,0),FALSE) | K6: =VLOOKUP($F6,raw_data_pax!$1:$1048576,MATCH(K$1,raw_data_pax!$1:$1,0),FALSE) | L6: =VLOOKUP($F6,raw_data_pax!$1:$1048576,MATCH(L$1,raw_data_pax!$1:$1,0),FALSE) | M6: =VLOOKUP($F6,raw_data_pax!$1:$1048576,MATCH(M$1,raw_data_pax!$1:$1,0),FALSE) | N6: =VLOOKUP($F6,raw_data_pax!$1:$1048576,MATCH(N$1,raw_data_pax!$1:$1,0),FALSE) | O6: =VLOOKUP($F6,raw_data_pax!$1:$1048576,MATCH(O$1,raw_data_pax!$1:$1,0),FALSE) | ... Q6: =VLOOKUP($F6,raw_data_pax!$1:$1048576,MATCH(Q$1,raw_data_pax!$1:$1,0),FALSE) | R6: =R2-R5 | S6: =S2-S5 | T6: =T2-T5 | U6: =U2-U5 | V6: =V2-V5 | W6: =W2-W5 | X6: =X2-X5 | Y6: =Y2-Y5 | ... BA6: =BA2-BA5
C7: Normal Passengers | D7: float0 | F7: 정규여객 | H7: =VLOOKUP($F7,raw_data_pax!$1:$1048576,MATCH(H$1,raw_data_pax!$1:$1,0),FALSE) | I7: =VLOOKUP($F7,raw_data_pax!$1:$1048576,MATCH(I$1,raw_data_pax!$1:$1,0),FALSE) | J7: =VLOOKUP($F7,raw_data_pax!$1:$1048576,MATCH(J$1,raw_data_pax!$1:$1,0),FALSE) | K7: =VLOOKUP($F7,raw_data_pax!$1:$1048576,MATCH(K$1,raw_data_pax!$1:$1,0),FALSE) | L7: =VLOOKUP($F7,raw_data_pax!$1:$1048576,MATCH(L$1,raw_data_pax!$1:$1,0),FALSE) | M7: =VLOOKUP($F7,raw_data_pax!$1:$1048576,MATCH(M$1,raw_data_pax!$1:$1,0),FALSE) | N7: =VLOOKUP($F7,raw_data_pax!$1:$1048576,MATCH(N$1,raw_data_pax!$1:$1,0),FALSE) | O7: =VLOOKUP($F7,raw_data_pax!$1:$1048576,MATCH(O$1,raw_data_pax!$1:$1,0),FALSE) | ... Q7: =VLOOKUP($F7,raw_data_pax!$1:$1048576,MATCH(Q$1,raw_data_pax!$1:$1,0),FALSE) | R7: =R2*R11 | S7: =S2*S11 | T7: =T2*T11 | U7: =U2*U11 | V7: =V2*V11 | W7: =W2*W11 | X7: =X2*X11 | Y7: =Y2*Y11 | ... BA7: =BA2*BA11
C8: Charter Passengers | D8: float0 | F8: 전세기여객 | H8: =VLOOKUP($F8,raw_data_pax!$1:$1048576,MATCH(H$1,raw_data_pax!$1:$1,0),FALSE) | I8: =VLOOKUP($F8,raw_data_pax!$1:$1048576,MATCH(I$1,raw_data_pax!$1:$1,0),FALSE) | J8: =VLOOKUP($F8,raw_data_pax!$1:$1048576,MATCH(J$1,raw_data_pax!$1:$1,0),FALSE) | K8: =VLOOKUP($F8,raw_data_pax!$1:$1048576,MATCH(K$1,raw_data_pax!$1:$1,0),FALSE) | L8: =VLOOKUP($F8,raw_data_pax!$1:$1048576,MATCH(L$1,raw_data_pax!$1:$1,0),FALSE) | M8: =VLOOKUP($F8,raw_data_pax!$1:$1048576,MATCH(M$1,raw_data_pax!$1:$1,0),FALSE) | N8: =VLOOKUP($F8,raw_data_pax!$1:$1048576,MATCH(N$1,raw_data_pax!$1:$1,0),FALSE) | O8: =VLOOKUP($F8,raw_data_pax!$1:$1048576,MATCH(O$1,raw_data_pax!$1:$1,0),FALSE) | ... Q8: =VLOOKUP($F8,raw_data_pax!$1:$1048576,MATCH(Q$1,raw_data_pax!$1:$1,0),FALSE) | R8: =R2-R7 | S8: =S2-S7 | T8: =T2-T7 | U8: =U2-U7 | V8: =V2-V7 | W8: =W2-W7 | X8: =X2-X7 | Y8: =Y2-Y7 | ... BA8: =BA2-BA7
C9: International Passengers(%)📝 | D9: percent0 | E9: O | G9: =IFERROR(SUMIF($H$159:$Q$159,"O",H9:Q9)/COUNTIFS($H$159:$Q$159,"O",H9:Q9,"<>0"),0) | H9: =H3/H2 | I9: =I3/I2 | J9: =J3/J2 | K9: =K3/K2 | L9: =L3/L2 | M9: =M3/M2 | N9: =N3/N2 | O9: =O3/O2 | ... Q9: =Q3/Q2 | R9: =G9 | S9: =R9 | T9: =S9 | U9: =T9 | V9: =U9 | W9: =V9 | X9: =W9 | Y9: =X9 | Z9: =Y9 | ... BA9: =AZ9
C10: Longhaul Passengers(%)📝 | D10: percent0 | E10: O | G10: =IFERROR(SUMIF($H$159:$Q$159,"O",H10:Q10)/COUNTIFS($H$159:$Q$159,"O",H10:Q10,"<>0"),0) | H10: =H5/H2 | I10: =I5/I2 | J10: =J5/J2 | K10: =K5/K2 | L10: =L5/L2 | M10: =M5/M2 | N10: =N5/N2 | O10: =O5/O2 | ... Q10: =Q5/Q2 | R10: =G10 | S10: =R10 | T10: =S10 | U10: =T10 | V10: =U10 | W10: =V10 | X10: =W10 | Y10: =X10 | Z10: =Y10 | ... BA10: =AZ10
C11: Regular Passengers(%)📝 | D11: percent0 | E11: O | G11: =IFERROR(SUMIF($H$159:$Q$159,"O",H11:Q11)/COUNTIFS($H$159:$Q$159,"O",H11:Q11,"<>0"),0) | H11: =H7/H2 | I11: =I7/I2 | J11: =J7/J2 | K11: =K7/K2 | L11: =L7/L2 | M11: =M7/M2 | N11: =N7/N2 | O11: =O7/O2 | ... Q11: =Q7/Q2 | R11: =G11 | S11: =R11 | T11: =S11 | U11: =T11 | V11: =U11 | W11: =V11 | X11: =W11 | Y11: =X11 | Z11: =Y11 | ... BA11: =AZ11
C12: Total Seats | D12: float0 | H12: =H13*H20 | I12: =I13*I20 | J12: =J13*J20 | K12: =K13*K20 | L12: =L13*L20 | M12: =M13*M20 | N12: =N13*N20 | O12: =O13*O20 | ... BA12: =BA13*BA20
C13: Average Seats Per Aircraft | D13: float0 | F13: 대당좌석수 | H13: =VLOOKUP($F13,raw_data_pax!$1:$1048576,MATCH(H$1,raw_data_pax!$1:$1,0),FALSE) | I13: =VLOOKUP($F13,raw_data_pax!$1:$1048576,MATCH(I$1,raw_data_pax!$1:$1,0),FALSE) | J13: =VLOOKUP($F13,raw_data_pax!$1:$1048576,MATCH(J$1,raw_data_pax!$1:$1,0),FALSE) | K13: =VLOOKUP($F13,raw_data_pax!$1:$1048576,MATCH(K$1,raw_data_pax!$1:$1,0),FALSE) | L13: =VLOOKUP($F13,raw_data_pax!$1:$1048576,MATCH(L$1,raw_data_pax!$1:$1,0),FALSE) | M13: =VLOOKUP($F13,raw_data_pax!$1:$1048576,MATCH(M$1,raw_data_pax!$1:$1,0),FALSE) | N13: =VLOOKUP($F13,raw_data_pax!$1:$1048576,MATCH(N$1,raw_data_pax!$1:$1,0),FALSE) | O13: =VLOOKUP($F13,raw_data_pax!$1:$1048576,MATCH(O$1,raw_data_pax!$1:$1,0),FALSE) | ... Q13: =VLOOKUP($F13,raw_data_pax!$1:$1048576,MATCH(Q$1,raw_data_pax!$1:$1,0),FALSE) | R13: =SUMPRODUCT(R51:R54,R31:R34) | S13: =SUMPRODUCT(S51:S54,S31:S34) | T13: =SUMPRODUCT(T51:T54,T31:T34) | U13: =SUMPRODUCT(U51:U54,U31:U34) | V13: =SUMPRODUCT(V51:V54,V31:V34) | W13: =SUMPRODUCT(W51:W54,W31:W34) | X13: =SUMPRODUCT(X51:X54,X31:X34) | Y13: =SUMPRODUCT(Y51:Y54,Y31:Y34) | ... BA13: =SUMPRODUCT(BA51:BA54,BA31:BA34)
C14: Load Factor(%)📝 | D14: percent0 | E14: O | F14: 탑승율 | G14: =SUMIF($H$160:$Q$160,"O",H14:Q14)/COUNTIFS($H$160:$Q$160,"O",H14:Q14,"<>0") | H14: =VLOOKUP($F14,raw_data_pax!$1:$1048576,MATCH(H$1,raw_data_pax!$1:$1,0),FALSE) | I14: =VLOOKUP($F14,raw_data_pax!$1:$1048576,MATCH(I$1,raw_data_pax!$1:$1,0),FALSE) | J14: =VLOOKUP($F14,raw_data_pax!$1:$1048576,MATCH(J$1,raw_data_pax!$1:$1,0),FALSE) | K14: =VLOOKUP($F14,raw_data_pax!$1:$1048576,MATCH(K$1,raw_data_pax!$1:$1,0),FALSE) | L14: =VLOOKUP($F14,raw_data_pax!$1:$1048576,MATCH(L$1,raw_data_pax!$1:$1,0),FALSE) | M14: =VLOOKUP($F14,raw_data_pax!$1:$1048576,MATCH(M$1,raw_data_pax!$1:$1,0),FALSE) | N14: =VLOOKUP($F14,raw_data_pax!$1:$1048576,MATCH(N$1,raw_data_pax!$1:$1,0),FALSE) | O14: =VLOOKUP($F14,raw_data_pax!$1:$1048576,MATCH(O$1,raw_data_pax!$1:$1,0),FALSE) | ... Q14: =VLOOKUP($F14,raw_data_pax!$1:$1048576,MATCH(Q$1,raw_data_pax!$1:$1,0),FALSE) | R14: =G14 | S14: =R14 | T14: =S14 | U14: =T14 | V14: =U14 | W14: =V14 | X14: =W14 | Y14: =X14 | Z14: =Y14 | ... BA14: =AZ14
C15: Average Passengers Per Aircraft | D15: float0 | F15: 대당여객 | H15: =VLOOKUP($F15,raw_data_pax!$1:$1048576,MATCH(H$1,raw_data_pax!$1:$1,0),FALSE) | I15: =VLOOKUP($F15,raw_data_pax!$1:$1048576,MATCH(I$1,raw_data_pax!$1:$1,0),FALSE) | J15: =VLOOKUP($F15,raw_data_pax!$1:$1048576,MATCH(J$1,raw_data_pax!$1:$1,0),FALSE) | K15: =VLOOKUP($F15,raw_data_pax!$1:$1048576,MATCH(K$1,raw_data_pax!$1:$1,0),FALSE) | L15: =VLOOKUP($F15,raw_data_pax!$1:$1048576,MATCH(L$1,raw_data_pax!$1:$1,0),FALSE) | M15: =VLOOKUP($F15,raw_data_pax!$1:$1048576,MATCH(M$1,raw_data_pax!$1:$1,0),FALSE) | N15: =VLOOKUP($F15,raw_data_pax!$1:$1048576,MATCH(N$1,raw_data_pax!$1:$1,0),FALSE) | O15: =VLOOKUP($F15,raw_data_pax!$1:$1048576,MATCH(O$1,raw_data_pax!$1:$1,0),FALSE) | ... Q15: =VLOOKUP($F15,raw_data_pax!$1:$1048576,MATCH(Q$1,raw_data_pax!$1:$1,0),FALSE) | R15: =R13*R14 | S15: =S13*S14 | T15: =T13*T14 | U15: =U13*U14 | V15: =V13*V14 | W15: =W13*W14 | X15: =X13*X14 | Y15: =Y13*Y14 | ... BA15: =BA13*BA14
C16: Annual Transfer Passengers | D16: float0 | F16: 연간환승승객 | H16: =VLOOKUP($F16,raw_data_pax!$1:$1048576,MATCH(H$1,raw_data_pax!$1:$1,0),FALSE) | I16: =VLOOKUP($F16,raw_data_pax!$1:$1048576,MATCH(I$1,raw_data_pax!$1:$1,0),FALSE) | J16: =VLOOKUP($F16,raw_data_pax!$1:$1048576,MATCH(J$1,raw_data_pax!$1:$1,0),FALSE) | K16: =VLOOKUP($F16,raw_data_pax!$1:$1048576,MATCH(K$1,raw_data_pax!$1:$1,0),FALSE) | L16: =VLOOKUP($F16,raw_data_pax!$1:$1048576,MATCH(L$1,raw_data_pax!$1:$1,0),FALSE) | M16: =VLOOKUP($F16,raw_data_pax!$1:$1048576,MATCH(M$1,raw_data_pax!$1:$1,0),FALSE) | N16: =VLOOKUP($F16,raw_data_pax!$1:$1048576,MATCH(N$1,raw_data_pax!$1:$1,0),FALSE) | O16: =VLOOKUP($F16,raw_data_pax!$1:$1048576,MATCH(O$1,raw_data_pax!$1:$1,0),FALSE) | ... Q16: =VLOOKUP($F16,raw_data_pax!$1:$1048576,MATCH(Q$1,raw_data_pax!$1:$1,0),FALSE) | R16: =R2*R17 | S16: =S2*S17 | T16: =T2*T17 | U16: =U2*U17 | V16: =V2*V17 | W16: =W2*W17 | X16: =X2*X17 | Y16: =Y2*Y17 | ... BA16: =BA2*BA17
C17: Transfer Rate(%)📝 | D17: percent0 | E17: O | F17: 환승율 | G17: =IFERROR(SUMIF($H$161:$Q$161,"O",H17:Q17)/COUNTIFS($H$161:$Q$161,"O",H17:Q17,"<>0"),0) | H17: =VLOOKUP($F17,raw_data_pax!$1:$1048576,MATCH(H$1,raw_data_pax!$1:$1,0),FALSE) | I17: =VLOOKUP($F17,raw_data_pax!$1:$1048576,MATCH(I$1,raw_data_pax!$1:$1,0),FALSE) | J17: =VLOOKUP($F17,raw_data_pax!$1:$1048576,MATCH(J$1,raw_data_pax!$1:$1,0),FALSE) | K17: =VLOOKUP($F17,raw_data_pax!$1:$1048576,MATCH(K$1,raw_data_pax!$1:$1,0),FALSE) | L17: =VLOOKUP($F17,raw_data_pax!$1:$1048576,MATCH(L$1,raw_data_pax!$1:$1,0),FALSE) | M17: =VLOOKUP($F17,raw_data_pax!$1:$1048576,MATCH(M$1,raw_data_pax!$1:$1,0),FALSE) | N17: =VLOOKUP($F17,raw_data_pax!$1:$1048576,MATCH(N$1,raw_data_pax!$1:$1,0),FALSE) | O17: =VLOOKUP($F17,raw_data_pax!$1:$1048576,MATCH(O$1,raw_data_pax!$1:$1,0),FALSE) | ... Q17: =VLOOKUP($F17,raw_data_pax!$1:$1048576,MATCH(Q$1,raw_data_pax!$1:$1,0),FALSE) | R17: =G17 | S17: =R17 | T17: =S17 | U17: =T17 | V17: =U17 | W17: =V17 | X17: =W17 | Y17: =X17 | Z17: =Y17 | ... BA17: =AZ17
C18: Average Crew Per Aircraft | D18: float0 | F18: 대당승무원 | H18: =VLOOKUP($F18,raw_data_pax!$1:$1048576,MATCH(H$1,raw_data_pax!$1:$1,0),FALSE) | I18: =VLOOKUP($F18,raw_data_pax!$1:$1048576,MATCH(I$1,raw_data_pax!$1:$1,0),FALSE) | J18: =VLOOKUP($F18,raw_data_pax!$1:$1048576,MATCH(J$1,raw_data_pax!$1:$1,0),FALSE) | K18: =VLOOKUP($F18,raw_data_pax!$1:$1048576,MATCH(K$1,raw_data_pax!$1:$1,0),FALSE) | L18: =VLOOKUP($F18,raw_data_pax!$1:$1048576,MATCH(L$1,raw_data_pax!$1:$1,0),FALSE) | M18: =VLOOKUP($F18,raw_data_pax!$1:$1048576,MATCH(M$1,raw_data_pax!$1:$1,0),FALSE) | N18: =VLOOKUP($F18,raw_data_pax!$1:$1048576,MATCH(N$1,raw_data_pax!$1:$1,0),FALSE) | O18: =VLOOKUP($F18,raw_data_pax!$1:$1048576,MATCH(O$1,raw_data_pax!$1:$1,0),FALSE) | ... Q18: =VLOOKUP($F18,raw_data_pax!$1:$1048576,MATCH(Q$1,raw_data_pax!$1:$1,0),FALSE) | R18: =IFERROR(SUMPRODUCT(R35:R38,R65:R68)/SUM(R35:R38),0) | S18: =IFERROR(SUMPRODUCT(S35:S38,S65:S68)/SUM(S35:S38),0) | T18: =IFERROR(SUMPRODUCT(T35:T38,T65:T68)/SUM(T35:T38),0) | U18: =IFERROR(SUMPRODUCT(U35:U38,U65:U68)/SUM(U35:U38),0) | V18: =IFERROR(SUMPRODUCT(V35:V38,V65:V68)/SUM(V35:V38),0) | W18: =IFERROR(SUMPRODUCT(W35:W38,W65:W68)/SUM(W35:W38),0) | X18: =IFERROR(SUMPRODUCT(X35:X38,X65:X68)/SUM(X35:X38),0) | Y18: =IFERROR(SUMPRODUCT(Y35:Y38,Y65:Y68)/SUM(Y35:Y38),0) | ... BA18: =IFERROR(SUMPRODUCT(BA35:BA38,BA65:BA68)/SUM(BA35:BA38),0)
C19: Crew Ratio(%) | D19: percent0 | F19: 승무원비율 | H19: =VLOOKUP($F19,raw_data_pax!$1:$1048576,MATCH(H$1,raw_data_pax!$1:$1,0),FALSE) | I19: =VLOOKUP($F19,raw_data_pax!$1:$1048576,MATCH(I$1,raw_data_pax!$1:$1,0),FALSE) | J19: =VLOOKUP($F19,raw_data_pax!$1:$1048576,MATCH(J$1,raw_data_pax!$1:$1,0),FALSE) | K19: =VLOOKUP($F19,raw_data_pax!$1:$1048576,MATCH(K$1,raw_data_pax!$1:$1,0),FALSE) | L19: =VLOOKUP($F19,raw_data_pax!$1:$1048576,MATCH(L$1,raw_data_pax!$1:$1,0),FALSE) | M19: =VLOOKUP($F19,raw_data_pax!$1:$1048576,MATCH(M$1,raw_data_pax!$1:$1,0),FALSE) | N19: =VLOOKUP($F19,raw_data_pax!$1:$1048576,MATCH(N$1,raw_data_pax!$1:$1,0),FALSE) | O19: =VLOOKUP($F19,raw_data_pax!$1:$1048576,MATCH(O$1,raw_data_pax!$1:$1,0),FALSE) | ... Q19: =VLOOKUP($F19,raw_data_pax!$1:$1048576,MATCH(Q$1,raw_data_pax!$1:$1,0),FALSE) | R19: =IFERROR(R18/R15,0) | S19: =IFERROR(S18/S15,0) | T19: =IFERROR(T18/T15,0) | U19: =IFERROR(U18/U15,0) | V19: =IFERROR(V18/V15,0) | W19: =IFERROR(W18/W15,0) | X19: =IFERROR(X18/X15,0) | Y19: =IFERROR(Y18/Y15,0) | ... BA19: =IFERROR(BA18/BA15,0)
B20: Passenger Flight Index | C20: Annual Movements | D20: float0 | F20: 연간운항 | H20: =VLOOKUP($F20,raw_data_pax!$1:$1048576,MATCH(H$1,raw_data_pax!$1:$1,0),FALSE) | I20: =VLOOKUP($F20,raw_data_pax!$1:$1048576,MATCH(I$1,raw_data_pax!$1:$1,0),FALSE) | J20: =VLOOKUP($F20,raw_data_pax!$1:$1048576,MATCH(J$1,raw_data_pax!$1:$1,0),FALSE) | K20: =VLOOKUP($F20,raw_data_pax!$1:$1048576,MATCH(K$1,raw_data_pax!$1:$1,0),FALSE) | L20: =VLOOKUP($F20,raw_data_pax!$1:$1048576,MATCH(L$1,raw_data_pax!$1:$1,0),FALSE) | M20: =VLOOKUP($F20,raw_data_pax!$1:$1048576,MATCH(M$1,raw_data_pax!$1:$1,0),FALSE) | N20: =VLOOKUP($F20,raw_data_pax!$1:$1048576,MATCH(N$1,raw_data_pax!$1:$1,0),FALSE) | O20: =VLOOKUP($F20,raw_data_pax!$1:$1048576,MATCH(O$1,raw_data_pax!$1:$1,0),FALSE) | ... Q20: =VLOOKUP($F20,raw_data_pax!$1:$1048576,MATCH(Q$1,raw_data_pax!$1:$1,0),FALSE) | R20: =IFERROR(R2/R15,0) | S20: =IFERROR(S2/S15,0) | T20: =IFERROR(T2/T15,0) | U20: =IFERROR(U2/U15,0) | V20: =IFERROR(V2/V15,0) | W20: =IFERROR(W2/W15,0) | X20: =IFERROR(X2/X15,0) | Y20: =IFERROR(Y2/Y15,0) | ... BA20: =IFERROR(BA2/BA15,0)
C21: Average Taxiing Time Per Aircraft(min) | D21: float0 | F21: 대당택싱평균 | H21: =VLOOKUP($F21,raw_data_pax!$1:$1048576,MATCH(H$1,raw_data_pax!$1:$1,0),FALSE) | I21: =VLOOKUP($F21,raw_data_pax!$1:$1048576,MATCH(I$1,raw_data_pax!$1:$1,0),FALSE) | J21: =VLOOKUP($F21,raw_data_pax!$1:$1048576,MATCH(J$1,raw_data_pax!$1:$1,0),FALSE) | K21: =VLOOKUP($F21,raw_data_pax!$1:$1048576,MATCH(K$1,raw_data_pax!$1:$1,0),FALSE) | L21: =VLOOKUP($F21,raw_data_pax!$1:$1048576,MATCH(L$1,raw_data_pax!$1:$1,0),FALSE) | M21: =VLOOKUP($F21,raw_data_pax!$1:$1048576,MATCH(M$1,raw_data_pax!$1:$1,0),FALSE) | N21: =VLOOKUP($F21,raw_data_pax!$1:$1048576,MATCH(N$1,raw_data_pax!$1:$1,0),FALSE) | O21: =VLOOKUP($F21,raw_data_pax!$1:$1048576,MATCH(O$1,raw_data_pax!$1:$1,0),FALSE) | ... Q21: =VLOOKUP($F21,raw_data_pax!$1:$1048576,MATCH(Q$1,raw_data_pax!$1:$1,0),FALSE)
C22: Average PeakTime TurnAround Standing Time(min) | D22: float0 | F22: 피크시간 턴어라운드편 평균주기시간(분) | H22: =VLOOKUP($F22,raw_data_pax!$1:$1048576,MATCH(H$1,raw_data_pax!$1:$1,0),FALSE) | I22: =VLOOKUP($F22,raw_data_pax!$1:$1048576,MATCH(I$1,raw_data_pax!$1:$1,0),FALSE) | J22: =VLOOKUP($F22,raw_data_pax!$1:$1048576,MATCH(J$1,raw_data_pax!$1:$1,0),FALSE) | K22: =VLOOKUP($F22,raw_data_pax!$1:$1048576,MATCH(K$1,raw_data_pax!$1:$1,0),FALSE) | L22: =VLOOKUP($F22,raw_data_pax!$1:$1048576,MATCH(L$1,raw_data_pax!$1:$1,0),FALSE) | M22: =VLOOKUP($F22,raw_data_pax!$1:$1048576,MATCH(M$1,raw_data_pax!$1:$1,0),FALSE) | N22: =VLOOKUP($F22,raw_data_pax!$1:$1048576,MATCH(N$1,raw_data_pax!$1:$1,0),FALSE) | O22: =VLOOKUP($F22,raw_data_pax!$1:$1048576,MATCH(O$1,raw_data_pax!$1:$1,0),FALSE) | ... Q22: =VLOOKUP($F22,raw_data_pax!$1:$1048576,MATCH(Q$1,raw_data_pax!$1:$1,0),FALSE)
C23: Average PeakTIme TurnAround Ground Time(min) | D23: float0 | F23: 피크시간 턴어라운드편 평균그라운드시간(분) | H23: =VLOOKUP($F23,raw_data_pax!$1:$1048576,MATCH(H$1,raw_data_pax!$1:$1,0),FALSE) | I23: =VLOOKUP($F23,raw_data_pax!$1:$1048576,MATCH(I$1,raw_data_pax!$1:$1,0),FALSE) | J23: =VLOOKUP($F23,raw_data_pax!$1:$1048576,MATCH(J$1,raw_data_pax!$1:$1,0),FALSE) | K23: =VLOOKUP($F23,raw_data_pax!$1:$1048576,MATCH(K$1,raw_data_pax!$1:$1,0),FALSE) | L23: =VLOOKUP($F23,raw_data_pax!$1:$1048576,MATCH(L$1,raw_data_pax!$1:$1,0),FALSE) | M23: =VLOOKUP($F23,raw_data_pax!$1:$1048576,MATCH(M$1,raw_data_pax!$1:$1,0),FALSE) | N23: =VLOOKUP($F23,raw_data_pax!$1:$1048576,MATCH(N$1,raw_data_pax!$1:$1,0),FALSE) | O23: =VLOOKUP($F23,raw_data_pax!$1:$1048576,MATCH(O$1,raw_data_pax!$1:$1,0),FALSE) | ... Q23: =VLOOKUP($F23,raw_data_pax!$1:$1048576,MATCH(Q$1,raw_data_pax!$1:$1,0),FALSE)
C24: Average TurnAround Standing Time(min) | D24: float0 | F24: 턴어라운드편 평균주기시간(분) | H24: =VLOOKUP($F24,raw_data_pax!$1:$1048576,MATCH(H$1,raw_data_pax!$1:$1,0),FALSE) | I24: =VLOOKUP($F24,raw_data_pax!$1:$1048576,MATCH(I$1,raw_data_pax!$1:$1,0),FALSE) | J24: =VLOOKUP($F24,raw_data_pax!$1:$1048576,MATCH(J$1,raw_data_pax!$1:$1,0),FALSE) | K24: =VLOOKUP($F24,raw_data_pax!$1:$1048576,MATCH(K$1,raw_data_pax!$1:$1,0),FALSE) | L24: =VLOOKUP($F24,raw_data_pax!$1:$1048576,MATCH(L$1,raw_data_pax!$1:$1,0),FALSE) | M24: =VLOOKUP($F24,raw_data_pax!$1:$1048576,MATCH(M$1,raw_data_pax!$1:$1,0),FALSE) | N24: =VLOOKUP($F24,raw_data_pax!$1:$1048576,MATCH(N$1,raw_data_pax!$1:$1,0),FALSE) | O24: =VLOOKUP($F24,raw_data_pax!$1:$1048576,MATCH(O$1,raw_data_pax!$1:$1,0),FALSE) | ... Q24: =VLOOKUP($F24,raw_data_pax!$1:$1048576,MATCH(Q$1,raw_data_pax!$1:$1,0),FALSE)
C25: Average TurnAround Ground Time(min) | D25: float0 | F25: 턴어라운드편 평균그라운드시간(분) | H25: =VLOOKUP($F25,raw_data_pax!$1:$1048576,MATCH(H$1,raw_data_pax!$1:$1,0),FALSE) | I25: =VLOOKUP($F25,raw_data_pax!$1:$1048576,MATCH(I$1,raw_data_pax!$1:$1,0),FALSE) | J25: =VLOOKUP($F25,raw_data_pax!$1:$1048576,MATCH(J$1,raw_data_pax!$1:$1,0),FALSE) | K25: =VLOOKUP($F25,raw_data_pax!$1:$1048576,MATCH(K$1,raw_data_pax!$1:$1,0),FALSE) | L25: =VLOOKUP($F25,raw_data_pax!$1:$1048576,MATCH(L$1,raw_data_pax!$1:$1,0),FALSE) | M25: =VLOOKUP($F25,raw_data_pax!$1:$1048576,MATCH(M$1,raw_data_pax!$1:$1,0),FALSE) | N25: =VLOOKUP($F25,raw_data_pax!$1:$1048576,MATCH(N$1,raw_data_pax!$1:$1,0),FALSE) | O25: =VLOOKUP($F25,raw_data_pax!$1:$1048576,MATCH(O$1,raw_data_pax!$1:$1,0),FALSE) | ... Q25: =VLOOKUP($F25,raw_data_pax!$1:$1048576,MATCH(Q$1,raw_data_pax!$1:$1,0),FALSE)
C26: Average Total Standing Time(min) | D26: float0 | F26: (오버나잇, 소산 포함) 평균주기시간(분) | H26: =VLOOKUP($F26,raw_data_pax!$1:$1048576,MATCH(H$1,raw_data_pax!$1:$1,0),FALSE) | I26: =VLOOKUP($F26,raw_data_pax!$1:$1048576,MATCH(I$1,raw_data_pax!$1:$1,0),FALSE) | J26: =VLOOKUP($F26,raw_data_pax!$1:$1048576,MATCH(J$1,raw_data_pax!$1:$1,0),FALSE) | K26: =VLOOKUP($F26,raw_data_pax!$1:$1048576,MATCH(K$1,raw_data_pax!$1:$1,0),FALSE) | L26: =VLOOKUP($F26,raw_data_pax!$1:$1048576,MATCH(L$1,raw_data_pax!$1:$1,0),FALSE) | M26: =VLOOKUP($F26,raw_data_pax!$1:$1048576,MATCH(M$1,raw_data_pax!$1:$1,0),FALSE) | N26: =VLOOKUP($F26,raw_data_pax!$1:$1048576,MATCH(N$1,raw_data_pax!$1:$1,0),FALSE) | O26: =VLOOKUP($F26,raw_data_pax!$1:$1048576,MATCH(O$1,raw_data_pax!$1:$1,0),FALSE) | ... Q26: =VLOOKUP($F26,raw_data_pax!$1:$1048576,MATCH(Q$1,raw_data_pax!$1:$1,0),FALSE)
C27: Average Total Ground Time(min) | D27: float0 | F27: (오버나잇, 소산 포함) 평균그라운드시간(분) | H27: =VLOOKUP($F27,raw_data_pax!$1:$1048576,MATCH(H$1,raw_data_pax!$1:$1,0),FALSE) | I27: =VLOOKUP($F27,raw_data_pax!$1:$1048576,MATCH(I$1,raw_data_pax!$1:$1,0),FALSE) | J27: =VLOOKUP($F27,raw_data_pax!$1:$1048576,MATCH(J$1,raw_data_pax!$1:$1,0),FALSE) | K27: =VLOOKUP($F27,raw_data_pax!$1:$1048576,MATCH(K$1,raw_data_pax!$1:$1,0),FALSE) | L27: =VLOOKUP($F27,raw_data_pax!$1:$1048576,MATCH(L$1,raw_data_pax!$1:$1,0),FALSE) | M27: =VLOOKUP($F27,raw_data_pax!$1:$1048576,MATCH(M$1,raw_data_pax!$1:$1,0),FALSE) | N27: =VLOOKUP($F27,raw_data_pax!$1:$1048576,MATCH(N$1,raw_data_pax!$1:$1,0),FALSE) | O27: =VLOOKUP($F27,raw_data_pax!$1:$1048576,MATCH(O$1,raw_data_pax!$1:$1,0),FALSE) | ... Q27: =VLOOKUP($F27,raw_data_pax!$1:$1048576,MATCH(Q$1,raw_data_pax!$1:$1,0),FALSE)
C28: Maximum Takeoff Weight Per Aircraft(lb) | D28: float0 | F28: 대당최대이륙중량 | H28: =VLOOKUP($F28,raw_data_pax!$1:$1048576,MATCH(H$1,raw_data_pax!$1:$1,0),FALSE) | I28: =VLOOKUP($F28,raw_data_pax!$1:$1048576,MATCH(I$1,raw_data_pax!$1:$1,0),FALSE) | J28: =VLOOKUP($F28,raw_data_pax!$1:$1048576,MATCH(J$1,raw_data_pax!$1:$1,0),FALSE) | K28: =VLOOKUP($F28,raw_data_pax!$1:$1048576,MATCH(K$1,raw_data_pax!$1:$1,0),FALSE) | L28: =VLOOKUP($F28,raw_data_pax!$1:$1048576,MATCH(L$1,raw_data_pax!$1:$1,0),FALSE) | M28: =VLOOKUP($F28,raw_data_pax!$1:$1048576,MATCH(M$1,raw_data_pax!$1:$1,0),FALSE) | N28: =VLOOKUP($F28,raw_data_pax!$1:$1048576,MATCH(N$1,raw_data_pax!$1:$1,0),FALSE) | O28: =VLOOKUP($F28,raw_data_pax!$1:$1048576,MATCH(O$1,raw_data_pax!$1:$1,0),FALSE) | ... Q28: =VLOOKUP($F28,raw_data_pax!$1:$1048576,MATCH(Q$1,raw_data_pax!$1:$1,0),FALSE)
C29: Average Flight Distance(km) | D29: float0 | F29: 비행거리평균(km) | H29: =VLOOKUP($F29,raw_data_pax!$1:$1048576,MATCH(H$1,raw_data_pax!$1:$1,0),FALSE) | I29: =VLOOKUP($F29,raw_data_pax!$1:$1048576,MATCH(I$1,raw_data_pax!$1:$1,0),FALSE) | J29: =VLOOKUP($F29,raw_data_pax!$1:$1048576,MATCH(J$1,raw_data_pax!$1:$1,0),FALSE) | K29: =VLOOKUP($F29,raw_data_pax!$1:$1048576,MATCH(K$1,raw_data_pax!$1:$1,0),FALSE) | L29: =VLOOKUP($F29,raw_data_pax!$1:$1048576,MATCH(L$1,raw_data_pax!$1:$1,0),FALSE) | M29: =VLOOKUP($F29,raw_data_pax!$1:$1048576,MATCH(M$1,raw_data_pax!$1:$1,0),FALSE) | N29: =VLOOKUP($F29,raw_data_pax!$1:$1048576,MATCH(N$1,raw_data_pax!$1:$1,0),FALSE) | O29: =VLOOKUP($F29,raw_data_pax!$1:$1048576,MATCH(O$1,raw_data_pax!$1:$1,0),FALSE) | ... Q29: =VLOOKUP($F29,raw_data_pax!$1:$1048576,MATCH(Q$1,raw_data_pax!$1:$1,0),FALSE)
C30: Payload Per Aircraft | D30: float0 | F30: 대당유상탑재중량 | H30: =VLOOKUP($F30,raw_data_pax!$1:$1048576,MATCH(H$1,raw_data_pax!$1:$1,0),FALSE) | I30: =VLOOKUP($F30,raw_data_pax!$1:$1048576,MATCH(I$1,raw_data_pax!$1:$1,0),FALSE) | J30: =VLOOKUP($F30,raw_data_pax!$1:$1048576,MATCH(J$1,raw_data_pax!$1:$1,0),FALSE) | K30: =VLOOKUP($F30,raw_data_pax!$1:$1048576,MATCH(K$1,raw_data_pax!$1:$1,0),FALSE) | L30: =VLOOKUP($F30,raw_data_pax!$1:$1048576,MATCH(L$1,raw_data_pax!$1:$1,0),FALSE) | M30: =VLOOKUP($F30,raw_data_pax!$1:$1048576,MATCH(M$1,raw_data_pax!$1:$1,0),FALSE) | N30: =VLOOKUP($F30,raw_data_pax!$1:$1048576,MATCH(N$1,raw_data_pax!$1:$1,0),FALSE) | O30: =VLOOKUP($F30,raw_data_pax!$1:$1048576,MATCH(O$1,raw_data_pax!$1:$1,0),FALSE) | ... Q30: =VLOOKUP($F30,raw_data_pax!$1:$1048576,MATCH(Q$1,raw_data_pax!$1:$1,0),FALSE)
A31: Flight Class Index | B31: FleetMIx | C31: =C151&"FleetMix📝" | D31: percent1 | E31: O | F31: =C151&"혼합율" | G31: =IFERROR(SUMIF($H$162:$Q$162,"O",H31:Q31)/COUNTIFS($H$162:$Q$162,"O",H31:Q31,"<>0"),0) | H31: =VLOOKUP($F31,raw_data_pax!$1:$1048576,MATCH(H$1,raw_data_pax!$1:$1,0),FALSE) | I31: =VLOOKUP($F31,raw_data_pax!$1:$1048576,MATCH(I$1,raw_data_pax!$1:$1,0),FALSE) | J31: =VLOOKUP($F31,raw_data_pax!$1:$1048576,MATCH(J$1,raw_data_pax!$1:$1,0),FALSE) | K31: =VLOOKUP($F31,raw_data_pax!$1:$1048576,MATCH(K$1,raw_data_pax!$1:$1,0),FALSE) | L31: =VLOOKUP($F31,raw_data_pax!$1:$1048576,MATCH(L$1,raw_data_pax!$1:$1,0),FALSE) | M31: =VLOOKUP($F31,raw_data_pax!$1:$1048576,MATCH(M$1,raw_data_pax!$1:$1,0),FALSE) | N31: =VLOOKUP($F31,raw_data_pax!$1:$1048576,MATCH(N$1,raw_data_pax!$1:$1,0),FALSE) | O31: =VLOOKUP($F31,raw_data_pax!$1:$1048576,MATCH(O$1,raw_data_pax!$1:$1,0),FALSE) | ... Q31: =VLOOKUP($F31,raw_data_pax!$1:$1048576,MATCH(Q$1,raw_data_pax!$1:$1,0),FALSE) | R31: =G31 | S31: =R31 | T31: =S31 | U31: =T31 | V31: =U31 | W31: =V31 | X31: =W31 | Y31: =X31 | Z31: =Y31 | ... BA31: =AZ31
C32: =C152&"FleetMix📝" | D32: percent1 | E32: O | F32: =C152&"혼합율" | G32: =IFERROR(SUMIF($H$162:$Q$162,"O",H32:Q32)/COUNTIFS($H$162:$Q$162,"O",H32:Q32,"<>0"),0) | H32: =VLOOKUP($F32,raw_data_pax!$1:$1048576,MATCH(H$1,raw_data_pax!$1:$1,0),FALSE) | I32: =VLOOKUP($F32,raw_data_pax!$1:$1048576,MATCH(I$1,raw_data_pax!$1:$1,0),FALSE) | J32: =VLOOKUP($F32,raw_data_pax!$1:$1048576,MATCH(J$1,raw_data_pax!$1:$1,0),FALSE) | K32: =VLOOKUP($F32,raw_data_pax!$1:$1048576,MATCH(K$1,raw_data_pax!$1:$1,0),FALSE) | L32: =VLOOKUP($F32,raw_data_pax!$1:$1048576,MATCH(L$1,raw_data_pax!$1:$1,0),FALSE) | M32: =VLOOKUP($F32,raw_data_pax!$1:$1048576,MATCH(M$1,raw_data_pax!$1:$1,0),FALSE) | N32: =VLOOKUP($F32,raw_data_pax!$1:$1048576,MATCH(N$1,raw_data_pax!$1:$1,0),FALSE) | O32: =VLOOKUP($F32,raw_data_pax!$1:$1048576,MATCH(O$1,raw_data_pax!$1:$1,0),FALSE) | ... Q32: =VLOOKUP($F32,raw_data_pax!$1:$1048576,MATCH(Q$1,raw_data_pax!$1:$1,0),FALSE) | R32: =G32 | S32: =R32 | T32: =S32 | U32: =T32 | V32: =U32 | W32: =V32 | X32: =W32 | Y32: =X32 | Z32: =Y32 | ... BA32: =AZ32
C33: =C153&"FleetMix📝" | D33: percent1 | E33: O | F33: =C153&"혼합율" | G33: =IFERROR(SUMIF($H$162:$Q$162,"O",H33:Q33)/COUNTIFS($H$162:$Q$162,"O",H33:Q33,"<>0"),0) | H33: =VLOOKUP($F33,raw_data_pax!$1:$1048576,MATCH(H$1,raw_data_pax!$1:$1,0),FALSE) | I33: =VLOOKUP($F33,raw_data_pax!$1:$1048576,MATCH(I$1,raw_data_pax!$1:$1,0),FALSE) | J33: =VLOOKUP($F33,raw_data_pax!$1:$1048576,MATCH(J$1,raw_data_pax!$1:$1,0),FALSE) | K33: =VLOOKUP($F33,raw_data_pax!$1:$1048576,MATCH(K$1,raw_data_pax!$1:$1,0),FALSE) | L33: =VLOOKUP($F33,raw_data_pax!$1:$1048576,MATCH(L$1,raw_data_pax!$1:$1,0),FALSE) | M33: =VLOOKUP($F33,raw_data_pax!$1:$1048576,MATCH(M$1,raw_data_pax!$1:$1,0),FALSE) | N33: =VLOOKUP($F33,raw_data_pax!$1:$1048576,MATCH(N$1,raw_data_pax!$1:$1,0),FALSE) | O33: =VLOOKUP($F33,raw_data_pax!$1:$1048576,MATCH(O$1,raw_data_pax!$1:$1,0),FALSE) | ... Q33: =VLOOKUP($F33,raw_data_pax!$1:$1048576,MATCH(Q$1,raw_data_pax!$1:$1,0),FALSE) | R33: =G33 | S33: =R33 | T33: =S33 | U33: =T33 | V33: =U33 | W33: =V33 | X33: =W33 | Y33: =X33 | Z33: =Y33 | ... BA33: =AZ33
C34: =C154&"FleetMix📝" | D34: percent1 | E34: O | F34: =C154&"혼합율" | G34: =IFERROR(SUMIF($H$162:$Q$162,"O",H34:Q34)/COUNTIFS($H$162:$Q$162,"O",H34:Q34,"<>0"),0) | H34: =VLOOKUP($F34,raw_data_pax!$1:$1048576,MATCH(H$1,raw_data_pax!$1:$1,0),FALSE) | I34: =VLOOKUP($F34,raw_data_pax!$1:$1048576,MATCH(I$1,raw_data_pax!$1:$1,0),FALSE) | J34: =VLOOKUP($F34,raw_data_pax!$1:$1048576,MATCH(J$1,raw_data_pax!$1:$1,0),FALSE) | K34: =VLOOKUP($F34,raw_data_pax!$1:$1048576,MATCH(K$1,raw_data_pax!$1:$1,0),FALSE) | L34: =VLOOKUP($F34,raw_data_pax!$1:$1048576,MATCH(L$1,raw_data_pax!$1:$1,0),FALSE) | M34: =VLOOKUP($F34,raw_data_pax!$1:$1048576,MATCH(M$1,raw_data_pax!$1:$1,0),FALSE) | N34: =VLOOKUP($F34,raw_data_pax!$1:$1048576,MATCH(N$1,raw_data_pax!$1:$1,0),FALSE) | O34: =VLOOKUP($F34,raw_data_pax!$1:$1048576,MATCH(O$1,raw_data_pax!$1:$1,0),FALSE) | ... Q34: =VLOOKUP($F34,raw_data_pax!$1:$1048576,MATCH(Q$1,raw_data_pax!$1:$1,0),FALSE) | R34: =G34 | S34: =R34 | T34: =S34 | U34: =T34 | V34: =U34 | W34: =V34 | X34: =W34 | Y34: =X34 | Z34: =Y34 | ... BA34: =AZ34
B35: Movements by Class | C35: =C151&"Movements" | D35: float0 | F35: =C151&"운항횟수" | H35: =VLOOKUP($F35,raw_data_pax!$1:$1048576,MATCH(H$1,raw_data_pax!$1:$1,0),FALSE) | I35: =VLOOKUP($F35,raw_data_pax!$1:$1048576,MATCH(I$1,raw_data_pax!$1:$1,0),FALSE) | J35: =VLOOKUP($F35,raw_data_pax!$1:$1048576,MATCH(J$1,raw_data_pax!$1:$1,0),FALSE) | K35: =VLOOKUP($F35,raw_data_pax!$1:$1048576,MATCH(K$1,raw_data_pax!$1:$1,0),FALSE) | L35: =VLOOKUP($F35,raw_data_pax!$1:$1048576,MATCH(L$1,raw_data_pax!$1:$1,0),FALSE) | M35: =VLOOKUP($F35,raw_data_pax!$1:$1048576,MATCH(M$1,raw_data_pax!$1:$1,0),FALSE) | N35: =VLOOKUP($F35,raw_data_pax!$1:$1048576,MATCH(N$1,raw_data_pax!$1:$1,0),FALSE) | O35: =VLOOKUP($F35,raw_data_pax!$1:$1048576,MATCH(O$1,raw_data_pax!$1:$1,0),FALSE) | ... Q35: =VLOOKUP($F35,raw_data_pax!$1:$1048576,MATCH(Q$1,raw_data_pax!$1:$1,0),FALSE) | R35: =R20*R31 | S35: =S20*S31 | T35: =T20*T31 | U35: =U20*U31 | V35: =V20*V31 | W35: =W20*W31 | X35: =X20*X31 | Y35: =Y20*Y31 | ... BA35: =BA20*BA31
C36: =C152&"Movements" | D36: float0 | F36: =C152&"운항횟수" | H36: =VLOOKUP($F36,raw_data_pax!$1:$1048576,MATCH(H$1,raw_data_pax!$1:$1,0),FALSE) | I36: =VLOOKUP($F36,raw_data_pax!$1:$1048576,MATCH(I$1,raw_data_pax!$1:$1,0),FALSE) | J36: =VLOOKUP($F36,raw_data_pax!$1:$1048576,MATCH(J$1,raw_data_pax!$1:$1,0),FALSE) | K36: =VLOOKUP($F36,raw_data_pax!$1:$1048576,MATCH(K$1,raw_data_pax!$1:$1,0),FALSE) | L36: =VLOOKUP($F36,raw_data_pax!$1:$1048576,MATCH(L$1,raw_data_pax!$1:$1,0),FALSE) | M36: =VLOOKUP($F36,raw_data_pax!$1:$1048576,MATCH(M$1,raw_data_pax!$1:$1,0),FALSE) | N36: =VLOOKUP($F36,raw_data_pax!$1:$1048576,MATCH(N$1,raw_data_pax!$1:$1,0),FALSE) | O36: =VLOOKUP($F36,raw_data_pax!$1:$1048576,MATCH(O$1,raw_data_pax!$1:$1,0),FALSE) | ... Q36: =VLOOKUP($F36,raw_data_pax!$1:$1048576,MATCH(Q$1,raw_data_pax!$1:$1,0),FALSE) | R36: =R20*R32 | S36: =S20*S32 | T36: =T20*T32 | U36: =U20*U32 | V36: =V20*V32 | W36: =W20*W32 | X36: =X20*X32 | Y36: =Y20*Y32 | ... BA36: =BA20*BA32
C37: =C153&"Movements" | D37: float0 | F37: =C153&"운항횟수" | H37: =VLOOKUP($F37,raw_data_pax!$1:$1048576,MATCH(H$1,raw_data_pax!$1:$1,0),FALSE) | I37: =VLOOKUP($F37,raw_data_pax!$1:$1048576,MATCH(I$1,raw_data_pax!$1:$1,0),FALSE) | J37: =VLOOKUP($F37,raw_data_pax!$1:$1048576,MATCH(J$1,raw_data_pax!$1:$1,0),FALSE) | K37: =VLOOKUP($F37,raw_data_pax!$1:$1048576,MATCH(K$1,raw_data_pax!$1:$1,0),FALSE) | L37: =VLOOKUP($F37,raw_data_pax!$1:$1048576,MATCH(L$1,raw_data_pax!$1:$1,0),FALSE) | M37: =VLOOKUP($F37,raw_data_pax!$1:$1048576,MATCH(M$1,raw_data_pax!$1:$1,0),FALSE) | N37: =VLOOKUP($F37,raw_data_pax!$1:$1048576,MATCH(N$1,raw_data_pax!$1:$1,0),FALSE) | O37: =VLOOKUP($F37,raw_data_pax!$1:$1048576,MATCH(O$1,raw_data_pax!$1:$1,0),FALSE) | ... Q37: =VLOOKUP($F37,raw_data_pax!$1:$1048576,MATCH(Q$1,raw_data_pax!$1:$1,0),FALSE) | R37: =R20*R33 | S37: =S20*S33 | T37: =T20*T33 | U37: =U20*U33 | V37: =V20*V33 | W37: =W20*W33 | X37: =X20*X33 | Y37: =Y20*Y33 | ... BA37: =BA20*BA33
C38: =C154&"Movements" | D38: float0 | F38: =C154&"운항횟수" | H38: =VLOOKUP($F38,raw_data_pax!$1:$1048576,MATCH(H$1,raw_data_pax!$1:$1,0),FALSE) | I38: =VLOOKUP($F38,raw_data_pax!$1:$1048576,MATCH(I$1,raw_data_pax!$1:$1,0),FALSE) | J38: =VLOOKUP($F38,raw_data_pax!$1:$1048576,MATCH(J$1,raw_data_pax!$1:$1,0),FALSE) | K38: =VLOOKUP($F38,raw_data_pax!$1:$1048576,MATCH(K$1,raw_data_pax!$1:$1,0),FALSE) | L38: =VLOOKUP($F38,raw_data_pax!$1:$1048576,MATCH(L$1,raw_data_pax!$1:$1,0),FALSE) | M38: =VLOOKUP($F38,raw_data_pax!$1:$1048576,MATCH(M$1,raw_data_pax!$1:$1,0),FALSE) | N38: =VLOOKUP($F38,raw_data_pax!$1:$1048576,MATCH(N$1,raw_data_pax!$1:$1,0),FALSE) | O38: =VLOOKUP($F38,raw_data_pax!$1:$1048576,MATCH(O$1,raw_data_pax!$1:$1,0),FALSE) | ... Q38: =VLOOKUP($F38,raw_data_pax!$1:$1048576,MATCH(Q$1,raw_data_pax!$1:$1,0),FALSE) | R38: =R20*R34 | S38: =S20*S34 | T38: =T20*T34 | U38: =U20*U34 | V38: =V20*V34 | W38: =W20*W34 | X38: =X20*X34 | Y38: =Y20*Y34 | ... BA38: =BA20*BA34
B39: MTOW by Class | C39: =C151&"MTOW" | D39: float0 | F39: =C151&"대당최대이륙중량" | G39: =IFERROR(SUMIF($H$172:$Q$172,"O",H39:Q39)/COUNTIFS($H$172:$Q$172,"O",H39:Q39,"<>0"),0) | H39: =VLOOKUP($F39,raw_data_pax!$1:$1048576,MATCH(H$1,raw_data_pax!$1:$1,0),FALSE) | I39: =VLOOKUP($F39,raw_data_pax!$1:$1048576,MATCH(I$1,raw_data_pax!$1:$1,0),FALSE) | J39: =VLOOKUP($F39,raw_data_pax!$1:$1048576,MATCH(J$1,raw_data_pax!$1:$1,0),FALSE) | K39: =VLOOKUP($F39,raw_data_pax!$1:$1048576,MATCH(K$1,raw_data_pax!$1:$1,0),FALSE) | L39: =VLOOKUP($F39,raw_data_pax!$1:$1048576,MATCH(L$1,raw_data_pax!$1:$1,0),FALSE) | M39: =VLOOKUP($F39,raw_data_pax!$1:$1048576,MATCH(M$1,raw_data_pax!$1:$1,0),FALSE) | N39: =VLOOKUP($F39,raw_data_pax!$1:$1048576,MATCH(N$1,raw_data_pax!$1:$1,0),FALSE) | O39: =VLOOKUP($F39,raw_data_pax!$1:$1048576,MATCH(O$1,raw_data_pax!$1:$1,0),FALSE) | ... Q39: =VLOOKUP($F39,raw_data_pax!$1:$1048576,MATCH(Q$1,raw_data_pax!$1:$1,0),FALSE) | R39: =G39 | S39: =R39 | T39: =S39 | U39: =T39 | V39: =U39 | W39: =V39 | X39: =W39 | Y39: =X39 | Z39: =Y39 | ... BA39: =AZ39
C40: =C152&"MTOW" | D40: float0 | F40: =C152&"대당최대이륙중량" | G40: =IFERROR(SUMIF($H$172:$Q$172,"O",H40:Q40)/COUNTIFS($H$172:$Q$172,"O",H40:Q40,"<>0"),0) | H40: =VLOOKUP($F40,raw_data_pax!$1:$1048576,MATCH(H$1,raw_data_pax!$1:$1,0),FALSE) | I40: =VLOOKUP($F40,raw_data_pax!$1:$1048576,MATCH(I$1,raw_data_pax!$1:$1,0),FALSE) | J40: =VLOOKUP($F40,raw_data_pax!$1:$1048576,MATCH(J$1,raw_data_pax!$1:$1,0),FALSE) | K40: =VLOOKUP($F40,raw_data_pax!$1:$1048576,MATCH(K$1,raw_data_pax!$1:$1,0),FALSE) | L40: =VLOOKUP($F40,raw_data_pax!$1:$1048576,MATCH(L$1,raw_data_pax!$1:$1,0),FALSE) | M40: =VLOOKUP($F40,raw_data_pax!$1:$1048576,MATCH(M$1,raw_data_pax!$1:$1,0),FALSE) | N40: =VLOOKUP($F40,raw_data_pax!$1:$1048576,MATCH(N$1,raw_data_pax!$1:$1,0),FALSE) | O40: =VLOOKUP($F40,raw_data_pax!$1:$1048576,MATCH(O$1,raw_data_pax!$1:$1,0),FALSE) | ... Q40: =VLOOKUP($F40,raw_data_pax!$1:$1048576,MATCH(Q$1,raw_data_pax!$1:$1,0),FALSE) | R40: =G40 | S40: =R40 | T40: =S40 | U40: =T40 | V40: =U40 | W40: =V40 | X40: =W40 | Y40: =X40 | Z40: =Y40 | ... BA40: =AZ40
...

Sheet Airside Demand
A1: top | B1: mid | C1: low | D1: decimal | E1: changeable | F1: 변수설명 | G1: Ref_Index | H1: =I1-1 | I1: =J1-1 | J1: =K1-1 | K1: =L1-1 | L1: =M1-1 | M1: =N1-1 | N1: =O1-1 | O1: =P1-1 | P1: =Q1-1 | Q1: =ref!B4 | R1: =Q1+1 | S1: =R1+1 | T1: =S1+1 | U1: =T1+1 | V1: =U1+1 | W1: =V1+1 | X1: =W1+1 | Y1: =X1+1 | ... BA1: =AZ1+1
A2: Airside Flight Index | C2: Annual Movements | D2: float0 | F2: 연간운항 | H2: =VLOOKUP($F2,raw_data_airside!$1:$1048576,MATCH(H$1,raw_data_airside!$1:$1,0),FALSE) | I2: =VLOOKUP($F2,raw_data_airside!$1:$1048576,MATCH(I$1,raw_data_airside!$1:$1,0),FALSE) | J2: =VLOOKUP($F2,raw_data_airside!$1:$1048576,MATCH(J$1,raw_data_airside!$1:$1,0),FALSE) | K2: =VLOOKUP($F2,raw_data_airside!$1:$1048576,MATCH(K$1,raw_data_airside!$1:$1,0),FALSE) | L2: =VLOOKUP($F2,raw_data_airside!$1:$1048576,MATCH(L$1,raw_data_airside!$1:$1,0),FALSE) | M2: =VLOOKUP($F2,raw_data_airside!$1:$1048576,MATCH(M$1,raw_data_airside!$1:$1,0),FALSE) | N2: =VLOOKUP($F2,raw_data_airside!$1:$1048576,MATCH(N$1,raw_data_airside!$1:$1,0),FALSE) | O2: =VLOOKUP($F2,raw_data_airside!$1:$1048576,MATCH(O$1,raw_data_airside!$1:$1,0),FALSE) | ... Q2: =VLOOKUP($F2,raw_data_airside!$1:$1048576,MATCH(Q$1,raw_data_airside!$1:$1,0),FALSE) | R2: ='Pax Demand'!R20+'Cargo Demand'!R3 | S2: ='Pax Demand'!S20+'Cargo Demand'!S3 | T2: ='Pax Demand'!T20+'Cargo Demand'!T3 | U2: ='Pax Demand'!U20+'Cargo Demand'!U3 | V2: ='Pax Demand'!V20+'Cargo Demand'!V3 | W2: ='Pax Demand'!W20+'Cargo Demand'!W3 | X2: ='Pax Demand'!X20+'Cargo Demand'!X3 | Y2: ='Pax Demand'!Y20+'Cargo Demand'!Y3 | ... BA2: ='Pax Demand'!BA20+'Cargo Demand'!BA3
C3: Average Taxiing Time Per Aircraft(min) | D3: float0 | F3: 대당택싱평균 | H3: =VLOOKUP($F3,raw_data_airside!$1:$1048576,MATCH(H$1,raw_data_airside!$1:$1,0),FALSE) | I3: =VLOOKUP($F3,raw_data_airside!$1:$1048576,MATCH(I$1,raw_data_airside!$1:$1,0),FALSE) | J3: =VLOOKUP($F3,raw_data_airside!$1:$1048576,MATCH(J$1,raw_data_airside!$1:$1,0),FALSE) | K3: =VLOOKUP($F3,raw_data_airside!$1:$1048576,MATCH(K$1,raw_data_airside!$1:$1,0),FALSE) | L3: =VLOOKUP($F3,raw_data_airside!$1:$1048576,MATCH(L$1,raw_data_airside!$1:$1,0),FALSE) | M3: =VLOOKUP($F3,raw_data_airside!$1:$1048576,MATCH(M$1,raw_data_airside!$1:$1,0),FALSE) | N3: =VLOOKUP($F3,raw_data_airside!$1:$1048576,MATCH(N$1,raw_data_airside!$1:$1,0),FALSE) | O3: =VLOOKUP($F3,raw_data_airside!$1:$1048576,MATCH(O$1,raw_data_airside!$1:$1,0),FALSE) | ... Q3: =VLOOKUP($F3,raw_data_airside!$1:$1048576,MATCH(Q$1,raw_data_airside!$1:$1,0),FALSE)
C4: Average PeakTime TurnAround Standing Time(min) | D4: float0 | F4: 피크시간 턴어라운드편 평균주기시간(분) | H4: =VLOOKUP($F4,raw_data_airside!$1:$1048576,MATCH(H$1,raw_data_airside!$1:$1,0),FALSE) | I4: =VLOOKUP($F4,raw_data_airside!$1:$1048576,MATCH(I$1,raw_data_airside!$1:$1,0),FALSE) | J4: =VLOOKUP($F4,raw_data_airside!$1:$1048576,MATCH(J$1,raw_data_airside!$1:$1,0),FALSE) | K4: =VLOOKUP($F4,raw_data_airside!$1:$1048576,MATCH(K$1,raw_data_airside!$1:$1,0),FALSE) | L4: =VLOOKUP($F4,raw_data_airside!$1:$1048576,MATCH(L$1,raw_data_airside!$1:$1,0),FALSE) | M4: =VLOOKUP($F4,raw_data_airside!$1:$1048576,MATCH(M$1,raw_data_airside!$1:$1,0),FALSE) | N4: =VLOOKUP($F4,raw_data_airside!$1:$1048576,MATCH(N$1,raw_data_airside!$1:$1,0),FALSE) | O4: =VLOOKUP($F4,raw_data_airside!$1:$1048576,MATCH(O$1,raw_data_airside!$1:$1,0),FALSE) | ... Q4: =VLOOKUP($F4,raw_data_airside!$1:$1048576,MATCH(Q$1,raw_data_airside!$1:$1,0),FALSE)
C5: Average PeakTIme TurnAround Ground Time(min) | D5: float0 | F5: 피크시간 턴어라운드편 평균그라운드시간(분) | H5: =VLOOKUP($F5,raw_data_airside!$1:$1048576,MATCH(H$1,raw_data_airside!$1:$1,0),FALSE) | I5: =VLOOKUP($F5,raw_data_airside!$1:$1048576,MATCH(I$1,raw_data_airside!$1:$1,0),FALSE) | J5: =VLOOKUP($F5,raw_data_airside!$1:$1048576,MATCH(J$1,raw_data_airside!$1:$1,0),FALSE) | K5: =VLOOKUP($F5,raw_data_airside!$1:$1048576,MATCH(K$1,raw_data_airside!$1:$1,0),FALSE) | L5: =VLOOKUP($F5,raw_data_airside!$1:$1048576,MATCH(L$1,raw_data_airside!$1:$1,0),FALSE) | M5: =VLOOKUP($F5,raw_data_airside!$1:$1048576,MATCH(M$1,raw_data_airside!$1:$1,0),FALSE) | N5: =VLOOKUP($F5,raw_data_airside!$1:$1048576,MATCH(N$1,raw_data_airside!$1:$1,0),FALSE) | O5: =VLOOKUP($F5,raw_data_airside!$1:$1048576,MATCH(O$1,raw_data_airside!$1:$1,0),FALSE) | ... Q5: =VLOOKUP($F5,raw_data_airside!$1:$1048576,MATCH(Q$1,raw_data_airside!$1:$1,0),FALSE)
C6: Average TurnAround Standing Time(min) | D6: float0 | F6: 턴어라운드편 평균주기시간(분) | H6: =VLOOKUP($F6,raw_data_airside!$1:$1048576,MATCH(H$1,raw_data_airside!$1:$1,0),FALSE) | I6: =VLOOKUP($F6,raw_data_airside!$1:$1048576,MATCH(I$1,raw_data_airside!$1:$1,0),FALSE) | J6: =VLOOKUP($F6,raw_data_airside!$1:$1048576,MATCH(J$1,raw_data_airside!$1:$1,0),FALSE) | K6: =VLOOKUP($F6,raw_data_airside!$1:$1048576,MATCH(K$1,raw_data_airside!$1:$1,0),FALSE) | L6: =VLOOKUP($F6,raw_data_airside!$1:$1048576,MATCH(L$1,raw_data_airside!$1:$1,0),FALSE) | M6: =VLOOKUP($F6,raw_data_airside!$1:$1048576,MATCH(M$1,raw_data_airside!$1:$1,0),FALSE) | N6: =VLOOKUP($F6,raw_data_airside!$1:$1048576,MATCH(N$1,raw_data_airside!$1:$1,0),FALSE) | O6: =VLOOKUP($F6,raw_data_airside!$1:$1048576,MATCH(O$1,raw_data_airside!$1:$1,0),FALSE) | ... Q6: =VLOOKUP($F6,raw_data_airside!$1:$1048576,MATCH(Q$1,raw_data_airside!$1:$1,0),FALSE)
C7: Average TurnAround Ground Time(min) | D7: float0 | F7: 턴어라운드편 평균그라운드시간(분) | H7: =VLOOKUP($F7,raw_data_airside!$1:$1048576,MATCH(H$1,raw_data_airside!$1:$1,0),FALSE) | I7: =VLOOKUP($F7,raw_data_airside!$1:$1048576,MATCH(I$1,raw_data_airside!$1:$1,0),FALSE) | J7: =VLOOKUP($F7,raw_data_airside!$1:$1048576,MATCH(J$1,raw_data_airside!$1:$1,0),FALSE) | K7: =VLOOKUP($F7,raw_data_airside!$1:$1048576,MATCH(K$1,raw_data_airside!$1:$1,0),FALSE) | L7: =VLOOKUP($F7,raw_data_airside!$1:$1048576,MATCH(L$1,raw_data_airside!$1:$1,0),FALSE) | M7: =VLOOKUP($F7,raw_data_airside!$1:$1048576,MATCH(M$1,raw_data_airside!$1:$1,0),FALSE) | N7: =VLOOKUP($F7,raw_data_airside!$1:$1048576,MATCH(N$1,raw_data_airside!$1:$1,0),FALSE) | O7: =VLOOKUP($F7,raw_data_airside!$1:$1048576,MATCH(O$1,raw_data_airside!$1:$1,0),FALSE) | ... Q7: =VLOOKUP($F7,raw_data_airside!$1:$1048576,MATCH(Q$1,raw_data_airside!$1:$1,0),FALSE)
C8: Average Total Standing Time(min) | D8: float0 | F8: (오버나잇, 소산 포함) 평균주기시간(분) | H8: =VLOOKUP($F8,raw_data_airside!$1:$1048576,MATCH(H$1,raw_data_airside!$1:$1,0),FALSE) | I8: =VLOOKUP($F8,raw_data_airside!$1:$1048576,MATCH(I$1,raw_data_airside!$1:$1,0),FALSE) | J8: =VLOOKUP($F8,raw_data_airside!$1:$1048576,MATCH(J$1,raw_data_airside!$1:$1,0),FALSE) | K8: =VLOOKUP($F8,raw_data_airside!$1:$1048576,MATCH(K$1,raw_data_airside!$1:$1,0),FALSE) | L8: =VLOOKUP($F8,raw_data_airside!$1:$1048576,MATCH(L$1,raw_data_airside!$1:$1,0),FALSE) | M8: =VLOOKUP($F8,raw_data_airside!$1:$1048576,MATCH(M$1,raw_data_airside!$1:$1,0),FALSE) | N8: =VLOOKUP($F8,raw_data_airside!$1:$1048576,MATCH(N$1,raw_data_airside!$1:$1,0),FALSE) | O8: =VLOOKUP($F8,raw_data_airside!$1:$1048576,MATCH(O$1,raw_data_airside!$1:$1,0),FALSE) | ... Q8: =VLOOKUP($F8,raw_data_airside!$1:$1048576,MATCH(Q$1,raw_data_airside!$1:$1,0),FALSE)
C9: Average Total Ground Time(min) | D9: float0 | F9: (오버나잇, 소산 포함) 평균그라운드시간(분) | H9: =VLOOKUP($F9,raw_data_airside!$1:$1048576,MATCH(H$1,raw_data_airside!$1:$1,0),FALSE) | I9: =VLOOKUP($F9,raw_data_airside!$1:$1048576,MATCH(I$1,raw_data_airside!$1:$1,0),FALSE) | J9: =VLOOKUP($F9,raw_data_airside!$1:$1048576,MATCH(J$1,raw_data_airside!$1:$1,0),FALSE) | K9: =VLOOKUP($F9,raw_data_airside!$1:$1048576,MATCH(K$1,raw_data_airside!$1:$1,0),FALSE) | L9: =VLOOKUP($F9,raw_data_airside!$1:$1048576,MATCH(L$1,raw_data_airside!$1:$1,0),FALSE) | M9: =VLOOKUP($F9,raw_data_airside!$1:$1048576,MATCH(M$1,raw_data_airside!$1:$1,0),FALSE) | N9: =VLOOKUP($F9,raw_data_airside!$1:$1048576,MATCH(N$1,raw_data_airside!$1:$1,0),FALSE) | O9: =VLOOKUP($F9,raw_data_airside!$1:$1048576,MATCH(O$1,raw_data_airside!$1:$1,0),FALSE) | ... Q9: =VLOOKUP($F9,raw_data_airside!$1:$1048576,MATCH(Q$1,raw_data_airside!$1:$1,0),FALSE)
C10: Maximum Takeoff Weight Per Aircraft(lb) | D10: float0 | F10: 대당최대이륙중량 | H10: =VLOOKUP($F10,raw_data_airside!$1:$1048576,MATCH(H$1,raw_data_airside!$1:$1,0),FALSE) | I10: =VLOOKUP($F10,raw_data_airside!$1:$1048576,MATCH(I$1,raw_data_airside!$1:$1,0),FALSE) | J10: =VLOOKUP($F10,raw_data_airside!$1:$1048576,MATCH(J$1,raw_data_airside!$1:$1,0),FALSE) | K10: =VLOOKUP($F10,raw_data_airside!$1:$1048576,MATCH(K$1,raw_data_airside!$1:$1,0),FALSE) | L10: =VLOOKUP($F10,raw_data_airside!$1:$1048576,MATCH(L$1,raw_data_airside!$1:$1,0),FALSE) | M10: =VLOOKUP($F10,raw_data_airside!$1:$1048576,MATCH(M$1,raw_data_airside!$1:$1,0),FALSE) | N10: =VLOOKUP($F10,raw_data_airside!$1:$1048576,MATCH(N$1,raw_data_airside!$1:$1,0),FALSE) | O10: =VLOOKUP($F10,raw_data_airside!$1:$1048576,MATCH(O$1,raw_data_airside!$1:$1,0),FALSE) | ... Q10: =VLOOKUP($F10,raw_data_airside!$1:$1048576,MATCH(Q$1,raw_data_airside!$1:$1,0),FALSE)
C11: Average Flight Distance(km) | D11: float0 | F11: 비행거리평균(km) | H11: =VLOOKUP($F11,raw_data_airside!$1:$1048576,MATCH(H$1,raw_data_airside!$1:$1,0),FALSE) | I11: =VLOOKUP($F11,raw_data_airside!$1:$1048576,MATCH(I$1,raw_data_airside!$1:$1,0),FALSE) | J11: =VLOOKUP($F11,raw_data_airside!$1:$1048576,MATCH(J$1,raw_data_airside!$1:$1,0),FALSE) | K11: =VLOOKUP($F11,raw_data_airside!$1:$1048576,MATCH(K$1,raw_data_airside!$1:$1,0),FALSE) | L11: =VLOOKUP($F11,raw_data_airside!$1:$1048576,MATCH(L$1,raw_data_airside!$1:$1,0),FALSE) | M11: =VLOOKUP($F11,raw_data_airside!$1:$1048576,MATCH(M$1,raw_data_airside!$1:$1,0),FALSE) | N11: =VLOOKUP($F11,raw_data_airside!$1:$1048576,MATCH(N$1,raw_data_airside!$1:$1,0),FALSE) | O11: =VLOOKUP($F11,raw_data_airside!$1:$1048576,MATCH(O$1,raw_data_airside!$1:$1,0),FALSE) | ... Q11: =VLOOKUP($F11,raw_data_airside!$1:$1048576,MATCH(Q$1,raw_data_airside!$1:$1,0),FALSE)
C12: Payload Per Aircraft | D12: float0 | F12: 대당유상탑재중량 | H12: =VLOOKUP($F12,raw_data_airside!$1:$1048576,MATCH(H$1,raw_data_airside!$1:$1,0),FALSE) | I12: =VLOOKUP($F12,raw_data_airside!$1:$1048576,MATCH(I$1,raw_data_airside!$1:$1,0),FALSE) | J12: =VLOOKUP($F12,raw_data_airside!$1:$1048576,MATCH(J$1,raw_data_airside!$1:$1,0),FALSE) | K12: =VLOOKUP($F12,raw_data_airside!$1:$1048576,MATCH(K$1,raw_data_airside!$1:$1,0),FALSE) | L12: =VLOOKUP($F12,raw_data_airside!$1:$1048576,MATCH(L$1,raw_data_airside!$1:$1,0),FALSE) | M12: =VLOOKUP($F12,raw_data_airside!$1:$1048576,MATCH(M$1,raw_data_airside!$1:$1,0),FALSE) | N12: =VLOOKUP($F12,raw_data_airside!$1:$1048576,MATCH(N$1,raw_data_airside!$1:$1,0),FALSE) | O12: =VLOOKUP($F12,raw_data_airside!$1:$1048576,MATCH(O$1,raw_data_airside!$1:$1,0),FALSE) | ... Q12: =VLOOKUP($F12,raw_data_airside!$1:$1048576,MATCH(Q$1,raw_data_airside!$1:$1,0),FALSE)
A13: Flight Class Index | B13: FleetMIx | C13: =C61&"FleetMix📝" | D13: percent1 | E13: O | F13: =C61&"혼합율" | G13: =IFERROR(SUMIF($H$72:$Q$72,"O",H13:Q13)/COUNTIFS($H$72:$Q$72,"O",H13:Q13,"<>0"),0) | H13: =VLOOKUP($F13,raw_data_airside!$1:$1048576,MATCH(H$1,raw_data_airside!$1:$1,0),FALSE) | I13: =VLOOKUP($F13,raw_data_airside!$1:$1048576,MATCH(I$1,raw_data_airside!$1:$1,0),FALSE) | J13: =VLOOKUP($F13,raw_data_airside!$1:$1048576,MATCH(J$1,raw_data_airside!$1:$1,0),FALSE) | K13: =VLOOKUP($F13,raw_data_airside!$1:$1048576,MATCH(K$1,raw_data_airside!$1:$1,0),FALSE) | L13: =VLOOKUP($F13,raw_data_airside!$1:$1048576,MATCH(L$1,raw_data_airside!$1:$1,0),FALSE) | M13: =VLOOKUP($F13,raw_data_airside!$1:$1048576,MATCH(M$1,raw_data_airside!$1:$1,0),FALSE) | N13: =VLOOKUP($F13,raw_data_airside!$1:$1048576,MATCH(N$1,raw_data_airside!$1:$1,0),FALSE) | O13: =VLOOKUP($F13,raw_data_airside!$1:$1048576,MATCH(O$1,raw_data_airside!$1:$1,0),FALSE) | ... Q13: =VLOOKUP($F13,raw_data_airside!$1:$1048576,MATCH(Q$1,raw_data_airside!$1:$1,0),FALSE) | R13: =G13 | S13: =R13 | T13: =S13 | U13: =T13 | V13: =U13 | W13: =V13 | X13: =W13 | Y13: =X13 | Z13: =Y13 | ... BA13: =AZ13
C14: =C62&"FleetMix📝" | D14: percent1 | E14: O | F14: =C62&"혼합율" | G14: =IFERROR(SUMIF($H$72:$Q$72,"O",H14:Q14)/COUNTIFS($H$72:$Q$72,"O",H14:Q14,"<>0"),0) | H14: =VLOOKUP($F14,raw_data_airside!$1:$1048576,MATCH(H$1,raw_data_airside!$1:$1,0),FALSE) | I14: =VLOOKUP($F14,raw_data_airside!$1:$1048576,MATCH(I$1,raw_data_airside!$1:$1,0),FALSE) | J14: =VLOOKUP($F14,raw_data_airside!$1:$1048576,MATCH(J$1,raw_data_airside!$1:$1,0),FALSE) | K14: =VLOOKUP($F14,raw_data_airside!$1:$1048576,MATCH(K$1,raw_data_airside!$1:$1,0),FALSE) | L14: =VLOOKUP($F14,raw_data_airside!$1:$1048576,MATCH(L$1,raw_data_airside!$1:$1,0),FALSE) | M14: =VLOOKUP($F14,raw_data_airside!$1:$1048576,MATCH(M$1,raw_data_airside!$1:$1,0),FALSE) | N14: =VLOOKUP($F14,raw_data_airside!$1:$1048576,MATCH(N$1,raw_data_airside!$1:$1,0),FALSE) | O14: =VLOOKUP($F14,raw_data_airside!$1:$1048576,MATCH(O$1,raw_data_airside!$1:$1,0),FALSE) | ... Q14: =VLOOKUP($F14,raw_data_airside!$1:$1048576,MATCH(Q$1,raw_data_airside!$1:$1,0),FALSE) | R14: =G14 | S14: =R14 | T14: =S14 | U14: =T14 | V14: =U14 | W14: =V14 | X14: =W14 | Y14: =X14 | Z14: =Y14 | ... BA14: =AZ14
C15: =C63&"FleetMix📝" | D15: percent1 | E15: O | F15: =C63&"혼합율" | G15: =IFERROR(SUMIF($H$72:$Q$72,"O",H15:Q15)/COUNTIFS($H$72:$Q$72,"O",H15:Q15,"<>0"),0) | H15: =VLOOKUP($F15,raw_data_airside!$1:$1048576,MATCH(H$1,raw_data_airside!$1:$1,0),FALSE) | I15: =VLOOKUP($F15,raw_data_airside!$1:$1048576,MATCH(I$1,raw_data_airside!$1:$1,0),FALSE) | J15: =VLOOKUP($F15,raw_data_airside!$1:$1048576,MATCH(J$1,raw_data_airside!$1:$1,0),FALSE) | K15: =VLOOKUP($F15,raw_data_airside!$1:$1048576,MATCH(K$1,raw_data_airside!$1:$1,0),FALSE) | L15: =VLOOKUP($F15,raw_data_airside!$1:$1048576,MATCH(L$1,raw_data_airside!$1:$1,0),FALSE) | M15: =VLOOKUP($F15,raw_data_airside!$1:$1048576,MATCH(M$1,raw_data_airside!$1:$1,0),FALSE) | N15: =VLOOKUP($F15,raw_data_airside!$1:$1048576,MATCH(N$1,raw_data_airside!$1:$1,0),FALSE) | O15: =VLOOKUP($F15,raw_data_airside!$1:$1048576,MATCH(O$1,raw_data_airside!$1:$1,0),FALSE) | ... Q15: =VLOOKUP($F15,raw_data_airside!$1:$1048576,MATCH(Q$1,raw_data_airside!$1:$1,0),FALSE) | R15: =G15 | S15: =R15 | T15: =S15 | U15: =T15 | V15: =U15 | W15: =V15 | X15: =W15 | Y15: =X15 | Z15: =Y15 | ... BA15: =AZ15
C16: =C64&"FleetMix📝" | D16: percent1 | E16: O | F16: =C64&"혼합율" | G16: =IFERROR(SUMIF($H$72:$Q$72,"O",H16:Q16)/COUNTIFS($H$72:$Q$72,"O",H16:Q16,"<>0"),0) | H16: =VLOOKUP($F16,raw_data_airside!$1:$1048576,MATCH(H$1,raw_data_airside!$1:$1,0),FALSE) | I16: =VLOOKUP($F16,raw_data_airside!$1:$1048576,MATCH(I$1,raw_data_airside!$1:$1,0),FALSE) | J16: =VLOOKUP($F16,raw_data_airside!$1:$1048576,MATCH(J$1,raw_data_airside!$1:$1,0),FALSE) | K16: =VLOOKUP($F16,raw_data_airside!$1:$1048576,MATCH(K$1,raw_data_airside!$1:$1,0),FALSE) | L16: =VLOOKUP($F16,raw_data_airside!$1:$1048576,MATCH(L$1,raw_data_airside!$1:$1,0),FALSE) | M16: =VLOOKUP($F16,raw_data_airside!$1:$1048576,MATCH(M$1,raw_data_airside!$1:$1,0),FALSE) | N16: =VLOOKUP($F16,raw_data_airside!$1:$1048576,MATCH(N$1,raw_data_airside!$1:$1,0),FALSE) | O16: =VLOOKUP($F16,raw_data_airside!$1:$1048576,MATCH(O$1,raw_data_airside!$1:$1,0),FALSE) | ... Q16: =VLOOKUP($F16,raw_data_airside!$1:$1048576,MATCH(Q$1,raw_data_airside!$1:$1,0),FALSE) | R16: =G16 | S16: =R16 | T16: =S16 | U16: =T16 | V16: =U16 | W16: =V16 | X16: =W16 | Y16: =X16 | Z16: =Y16 | ... BA16: =AZ16
B17: Movements by Class | C17: =C61&"Movements" | D17: float0 | F17: =C61&"운항횟수" | H17: =VLOOKUP($F17,raw_data_airside!$1:$1048576,MATCH(H$1,raw_data_airside!$1:$1,0),FALSE) | I17: =VLOOKUP($F17,raw_data_airside!$1:$1048576,MATCH(I$1,raw_data_airside!$1:$1,0),FALSE) | J17: =VLOOKUP($F17,raw_data_airside!$1:$1048576,MATCH(J$1,raw_data_airside!$1:$1,0),FALSE) | K17: =VLOOKUP($F17,raw_data_airside!$1:$1048576,MATCH(K$1,raw_data_airside!$1:$1,0),FALSE) | L17: =VLOOKUP($F17,raw_data_airside!$1:$1048576,MATCH(L$1,raw_data_airside!$1:$1,0),FALSE) | M17: =VLOOKUP($F17,raw_data_airside!$1:$1048576,MATCH(M$1,raw_data_airside!$1:$1,0),FALSE) | N17: =VLOOKUP($F17,raw_data_airside!$1:$1048576,MATCH(N$1,raw_data_airside!$1:$1,0),FALSE) | O17: =VLOOKUP($F17,raw_data_airside!$1:$1048576,MATCH(O$1,raw_data_airside!$1:$1,0),FALSE) | ... Q17: =VLOOKUP($F17,raw_data_airside!$1:$1048576,MATCH(Q$1,raw_data_airside!$1:$1,0),FALSE) | R17: =R2*R13 | S17: =S2*S13 | T17: =T2*T13 | U17: =U2*U13 | V17: =V2*V13 | W17: =W2*W13 | X17: =X2*X13 | Y17: =Y2*Y13 | ... BA17: =BA2*BA13
C18: =C62&"Movements" | D18: float0 | F18: =C62&"운항횟수" | H18: =VLOOKUP($F18,raw_data_airside!$1:$1048576,MATCH(H$1,raw_data_airside!$1:$1,0),FALSE) | I18: =VLOOKUP($F18,raw_data_airside!$1:$1048576,MATCH(I$1,raw_data_airside!$1:$1,0),FALSE) | J18: =VLOOKUP($F18,raw_data_airside!$1:$1048576,MATCH(J$1,raw_data_airside!$1:$1,0),FALSE) | K18: =VLOOKUP($F18,raw_data_airside!$1:$1048576,MATCH(K$1,raw_data_airside!$1:$1,0),FALSE) | L18: =VLOOKUP($F18,raw_data_airside!$1:$1048576,MATCH(L$1,raw_data_airside!$1:$1,0),FALSE) | M18: =VLOOKUP($F18,raw_data_airside!$1:$1048576,MATCH(M$1,raw_data_airside!$1:$1,0),FALSE) | N18: =VLOOKUP($F18,raw_data_airside!$1:$1048576,MATCH(N$1,raw_data_airside!$1:$1,0),FALSE) | O18: =VLOOKUP($F18,raw_data_airside!$1:$1048576,MATCH(O$1,raw_data_airside!$1:$1,0),FALSE) | ... Q18: =VLOOKUP($F18,raw_data_airside!$1:$1048576,MATCH(Q$1,raw_data_airside!$1:$1,0),FALSE) | R18: =R2*R14 | S18: =S2*S14 | T18: =T2*T14 | U18: =U2*U14 | V18: =V2*V14 | W18: =W2*W14 | X18: =X2*X14 | Y18: =Y2*Y14 | ... BA18: =BA2*BA14
C19: =C63&"Movements" | D19: float0 | F19: =C63&"운항횟수" | H19: =VLOOKUP($F19,raw_data_airside!$1:$1048576,MATCH(H$1,raw_data_airside!$1:$1,0),FALSE) | I19: =VLOOKUP($F19,raw_data_airside!$1:$1048576,MATCH(I$1,raw_data_airside!$1:$1,0),FALSE) | J19: =VLOOKUP($F19,raw_data_airside!$1:$1048576,MATCH(J$1,raw_data_airside!$1:$1,0),FALSE) | K19: =VLOOKUP($F19,raw_data_airside!$1:$1048576,MATCH(K$1,raw_data_airside!$1:$1,0),FALSE) | L19: =VLOOKUP($F19,raw_data_airside!$1:$1048576,MATCH(L$1,raw_data_airside!$1:$1,0),FALSE) | M19: =VLOOKUP($F19,raw_data_airside!$1:$1048576,MATCH(M$1,raw_data_airside!$1:$1,0),FALSE) | N19: =VLOOKUP($F19,raw_data_airside!$1:$1048576,MATCH(N$1,raw_data_airside!$1:$1,0),FALSE) | O19: =VLOOKUP($F19,raw_data_airside!$1:$1048576,MATCH(O$1,raw_data_airside!$1:$1,0),FALSE) | ... Q19: =VLOOKUP($F19,raw_data_airside!$1:$1048576,MATCH(Q$1,raw_data_airside!$1:$1,0),FALSE) | R19: =R2*R15 | S19: =S2*S15 | T19: =T2*T15 | U19: =U2*U15 | V19: =V2*V15 | W19: =W2*W15 | X19: =X2*X15 | Y19: =Y2*Y15 | ... BA19: =BA2*BA15
C20: =C64&"Movements" | D20: float0 | F20: =C64&"운항횟수" | H20: =VLOOKUP($F20,raw_data_airside!$1:$1048576,MATCH(H$1,raw_data_airside!$1:$1,0),FALSE) | I20: =VLOOKUP($F20,raw_data_airside!$1:$1048576,MATCH(I$1,raw_data_airside!$1:$1,0),FALSE) | J20: =VLOOKUP($F20,raw_data_airside!$1:$1048576,MATCH(J$1,raw_data_airside!$1:$1,0),FALSE) | K20: =VLOOKUP($F20,raw_data_airside!$1:$1048576,MATCH(K$1,raw_data_airside!$1:$1,0),FALSE) | L20: =VLOOKUP($F20,raw_data_airside!$1:$1048576,MATCH(L$1,raw_data_airside!$1:$1,0),FALSE) | M20: =VLOOKUP($F20,raw_data_airside!$1:$1048576,MATCH(M$1,raw_data_airside!$1:$1,0),FALSE) | N20: =VLOOKUP($F20,raw_data_airside!$1:$1048576,MATCH(N$1,raw_data_airside!$1:$1,0),FALSE) | O20: =VLOOKUP($F20,raw_data_airside!$1:$1048576,MATCH(O$1,raw_data_airside!$1:$1,0),FALSE) | ... Q20: =VLOOKUP($F20,raw_data_airside!$1:$1048576,MATCH(Q$1,raw_data_airside!$1:$1,0),FALSE) | R20: =R2*R16 | S20: =S2*S16 | T20: =T2*T16 | U20: =U2*U16 | V20: =V2*V16 | W20: =W2*W16 | X20: =X2*X16 | Y20: =Y2*Y16 | ... BA20: =BA2*BA16
B21: MTOW by Class | C21: =C61&"MTOW" | D21: float0 | F21: =C61&"대당최대이륙중량" | G21: =IFERROR(SUMIF($H$82:$Q$82,"O",H21:Q21)/COUNTIFS($H$82:$Q$82,"O",H21:Q21,"<>0"),0) | H21: =VLOOKUP($F21,raw_data_airside!$1:$1048576,MATCH(H$1,raw_data_airside!$1:$1,0),FALSE) | I21: =VLOOKUP($F21,raw_data_airside!$1:$1048576,MATCH(I$1,raw_data_airside!$1:$1,0),FALSE) | J21: =VLOOKUP($F21,raw_data_airside!$1:$1048576,MATCH(J$1,raw_data_airside!$1:$1,0),FALSE) | K21: =VLOOKUP($F21,raw_data_airside!$1:$1048576,MATCH(K$1,raw_data_airside!$1:$1,0),FALSE) | L21: =VLOOKUP($F21,raw_data_airside!$1:$1048576,MATCH(L$1,raw_data_airside!$1:$1,0),FALSE) | M21: =VLOOKUP($F21,raw_data_airside!$1:$1048576,MATCH(M$1,raw_data_airside!$1:$1,0),FALSE) | N21: =VLOOKUP($F21,raw_data_airside!$1:$1048576,MATCH(N$1,raw_data_airside!$1:$1,0),FALSE) | O21: =VLOOKUP($F21,raw_data_airside!$1:$1048576,MATCH(O$1,raw_data_airside!$1:$1,0),FALSE) | ... Q21: =VLOOKUP($F21,raw_data_airside!$1:$1048576,MATCH(Q$1,raw_data_airside!$1:$1,0),FALSE) | R21: =G21 | S21: =R21 | T21: =S21 | U21: =T21 | V21: =U21 | W21: =V21 | X21: =W21 | Y21: =X21 | Z21: =Y21 | ... BA21: =AZ21
C22: =C62&"MTOW" | D22: float0 | F22: =C62&"대당최대이륙중량" | G22: =IFERROR(SUMIF($H$82:$Q$82,"O",H22:Q22)/COUNTIFS($H$82:$Q$82,"O",H22:Q22,"<>0"),0) | H22: =VLOOKUP($F22,raw_data_airside!$1:$1048576,MATCH(H$1,raw_data_airside!$1:$1,0),FALSE) | I22: =VLOOKUP($F22,raw_data_airside!$1:$1048576,MATCH(I$1,raw_data_airside!$1:$1,0),FALSE) | J22: =VLOOKUP($F22,raw_data_airside!$1:$1048576,MATCH(J$1,raw_data_airside!$1:$1,0),FALSE) | K22: =VLOOKUP($F22,raw_data_airside!$1:$1048576,MATCH(K$1,raw_data_airside!$1:$1,0),FALSE) | L22: =VLOOKUP($F22,raw_data_airside!$1:$1048576,MATCH(L$1,raw_data_airside!$1:$1,0),FALSE) | M22: =VLOOKUP($F22,raw_data_airside!$1:$1048576,MATCH(M$1,raw_data_airside!$1:$1,0),FALSE) | N22: =VLOOKUP($F22,raw_data_airside!$1:$1048576,MATCH(N$1,raw_data_airside!$1:$1,0),FALSE) | O22: =VLOOKUP($F22,raw_data_airside!$1:$1048576,MATCH(O$1,raw_data_airside!$1:$1,0),FALSE) | ... Q22: =VLOOKUP($F22,raw_data_airside!$1:$1048576,MATCH(Q$1,raw_data_airside!$1:$1,0),FALSE) | R22: =G22 | S22: =R22 | T22: =S22 | U22: =T22 | V22: =U22 | W22: =V22 | X22: =W22 | Y22: =X22 | Z22: =Y22 | ... BA22: =AZ22
C23: =C63&"MTOW" | D23: float0 | F23: =C63&"대당최대이륙중량" | G23: =IFERROR(SUMIF($H$82:$Q$82,"O",H23:Q23)/COUNTIFS($H$82:$Q$82,"O",H23:Q23,"<>0"),0) | H23: =VLOOKUP($F23,raw_data_airside!$1:$1048576,MATCH(H$1,raw_data_airside!$1:$1,0),FALSE) | I23: =VLOOKUP($F23,raw_data_airside!$1:$1048576,MATCH(I$1,raw_data_airside!$1:$1,0),FALSE) | J23: =VLOOKUP($F23,raw_data_airside!$1:$1048576,MATCH(J$1,raw_data_airside!$1:$1,0),FALSE) | K23: =VLOOKUP($F23,raw_data_airside!$1:$1048576,MATCH(K$1,raw_data_airside!$1:$1,0),FALSE) | L23: =VLOOKUP($F23,raw_data_airside!$1:$1048576,MATCH(L$1,raw_data_airside!$1:$1,0),FALSE) | M23: =VLOOKUP($F23,raw_data_airside!$1:$1048576,MATCH(M$1,raw_data_airside!$1:$1,0),FALSE) | N23: =VLOOKUP($F23,raw_data_airside!$1:$1048576,MATCH(N$1,raw_data_airside!$1:$1,0),FALSE) | O23: =VLOOKUP($F23,raw_data_airside!$1:$1048576,MATCH(O$1,raw_data_airside!$1:$1,0),FALSE) | ... Q23: =VLOOKUP($F23,raw_data_airside!$1:$1048576,MATCH(Q$1,raw_data_airside!$1:$1,0),FALSE) | R23: =G23 | S23: =R23 | T23: =S23 | U23: =T23 | V23: =U23 | W23: =V23 | X23: =W23 | Y23: =X23 | Z23: =Y23 | ... BA23: =AZ23
