Workbook

Sheet watf_2016
B1: Region | C1: Entity | D1: Metric | E1: 2015 | F1: 2016 | G1: 2017 | H1: 2018 | I1: 2019 | J1: 2020 | K1: 2021 | L1: 2022 | M1: 2023 | N1: 2024 | O1: 2025 | P1: 2026 | Q1: 2027 | R1: 2028 | S1: 2029 | T1: 2030 | U1: 2031 | V1: 2032 | W1: 2033 | X1: 2034 | Y1: 2035 | Z1: 2036 | AA1: 2037 | AB1: 2038 | AC1: 2039 | AD1: 2040
A2: =D2&"_"&C2 -> Total Passengers_Zambia | B2: Africa | C2: Zambia | D2: Total Passengers | E2: 1581561 | F2: 1580311 | G2: 1558152 | H2: 1577896 | I2: 1623928 | J2: 1708052 | K2: 1781587 | L2: 1857935 | M2: 1933089 | N2: 1998742 | O2: 2040616 | P2: 2106573 | Q2: 2191488 | R2: 2257996 | S2: 2337325 | T2: 2401727 | U2: 2469853 | V2: 2575277 | W2: 2681840 | X2: 2790375 | Y2: 2899680 | Z2: 3007120 | AA2: 3130669 | AB2: 3258816 | AC2: 3389439 | AD2: 3522657
A3: =D3&"_"&C3 -> International Passengers_Zambia | B3: Africa | C3: Zambia | D3: International Passengers | E3: 1085451 | F3: 1120771 | G3: 1128838 | H3: 1149901 | I3: 1183361 | J3: 1237982 | K3: 1284515 | L3: 1328611 | M3: 1368558 | N3: 1400975 | O3: 1414411 | P3: 1440330 | Q3: 1474000 | R3: 1493521 | S3: 1519756 | T3: 1533856 | U3: 1548300 | V3: 1578344 | W3: 1608143 | X3: 1637668 | Y3: 1666358 | Z3: 1691408 | AA3: 1723550 | AB3: 1757187 | AC3: 1790558 | AD3: 1823435
A4: =D4&"_"&C4 -> Domestic Passengers_Zambia | B4: Africa | C4: Zambia | D4: Domestic Passengers | E4: 289835 | F4: 253597 | G4: 213884 | H4: 204483 | I4: 206595 | J4: 220366 | K4: 232683 | L4: 247424 | M4: 263460 | N4: 278415 | O4: 290992 | P4: 309485 | Q4: 333434 | R4: 355807 | S4: 381046 | T4: 405574 | U4: 431739 | V4: 468903 | W4: 507161 | X4: 546852 | Y4: 587617 | Z4: 629821 | AA4: 676667 | AB4: 725222 | AC4: 775343 | AD4: 826981
A5: =D5&"_"&C5 -> Total Cargo_Zambia | B5: Africa | C5: Zambia | D5: Total Cargo | E5: 15999 | F5: 21347.706 | G5: 25379.133 | H5: 28859.788 | I5: 32095.973 | J5: 33831.065 | K5: 35168.597 | L5: 36628.288 | M5: 38024.192 | N5: 39080.974 | O5: 39919.77 | P5: 41092.136 | Q5: 42829.74 | R5: 43760.503 | S5: 45006.79 | T5: 45658.983 | U5: 46508.409 | V5: 48453.569 | W5: 50186.511 | X5: 51813.927 | Y5: 53294.057 | Z5: 54674.109 | AA5: 56255.308 | AB5: 57676.595 | AC5: 58936.322 | AD5: 60022.813
A6: =D6&"_"&C6 -> Total Aircraft Movements_Zambia | B6: Africa | C6: Zambia | D6: Total Aircraft Movements | E6: 68150 | F6: 65100.169 | G6: 66570.546 | H6: 67358.45 | I6: 68093.525 | J6: 69036.569 | K6: 69438.743 | L6: 69869.644 | M6: 70190.163 | N6: 70128.428 | O6: 69228.821 | P6: 69069.656 | Q6: 69461.319 | R6: 69194.022 | S6: 69265.833 | T6: 68858.56 | U6: 68513.612 | V6: 68980.927 | W6: 69285.878 | X6: 69548.754 | Y6: 69706.176 | Z6: 69735.128 | AA6: 69982.968 | AB6: 70173.989 | AC6: 70280.12 | AD6: 70310.324
A7: =D7&"_"&C7 -> Total Passengers_Vietnam | B7: Asia-Pacific | C7: Vietnam | D7: Total Passengers | E7: 63125461 | F7: 72733238 | G7: 85137052 | H7: 97730317 | I7: 111137061 | J7: 125704700 | K7: 141252500 | L7: 157734210 | M7: 175172422 | N7: 193622636 | O7: 213629722 | P7: 232673725 | Q7: 252864214 | R7: 274426394 | S7: 297486922 | T7: 322134740 | U7: 348436024 | V7: 375414171 | W7: 404079581 | X7: 434518353 | Y7: 466806089 | Z7: 501019458 | AA7: 534813013 | AB7: 570463536 | AC7: 608043784 | AD7: 647624912
A8: =D8&"_"&C8 -> International Passengers_Vietnam | B8: Asia-Pacific | C8: Vietnam | D8: International Passengers | E8: 19109555 | F8: 20519067 | G8: 21925284 | H8: 25042994 | I8: 29403314 | J8: 35766016 | K8: 43105821 | L8: 51406538 | M8: 60725620 | N8: 71006819 | O8: 82790779 | P8: 94833527 | Q8: 108041294 | R8: 122490101 | S8: 138330522 | T8: 155614676 | U8: 174479943 | V8: 194348194 | W8: 215769564 | X8: 238817028 | Y8: 263631228 | Z8: 290212305 | AA8: 317078435 | AB8: 345655425 | AC8: 376012054 | AD8: 408257788
A9: =D9&"_"&C9 -> Domestic Passengers_Vietnam | B9: Asia-Pacific | C9: Vietnam | D9: Domestic Passengers | E9: 44015906 | F9: 52146303 | G9: 63088068 | H9: 72479854 | I9: 81369038 | J9: 89367431 | K9: 97322739 | L9: 105196887 | M9: 112956413 | N9: 120707774 | O9: 128428468 | P9: 134871239 | Q9: 141183956 | R9: 147501200 | S9: 153776350 | T9: 160039693 | U9: 166190000 | V9: 171838235 | W9: 177394168 | X9: 182857752 | Y9: 188192829 | Z9: 193419472 | AA9: 197811753 | AB9: 202065822 | AC9: 206167707 | AD9: 210051612
A10: =D10&"_"&C10 -> Total Cargo_Vietnam | B10: Asia-Pacific | C10: Vietnam | D10: Total Cargo | E10: 973401 | F10: 1163656 | G10: 1416299.1 | H10: 1673169.3 | I10: 1948190.7 | J10: 2249115.2 | K10: 2571910 | L10: 2915543.2 | M10: 3280518.7 | N10: 3668075.1 | O10: 4090370.1 | P10: 4491175.7 | Q10: 4917562.9 | R10: 5374556.6 | S10: 5864983 | T10: 6390826.6 | U10: 6953564 | V10: 7531404.2 | W10: 8146892.4 | X10: 8801949.6 | Y10: 9498262.7 | Z10: 10237543 | AA10: 10967455 | AB10: 11738802 | AC10: 12553207 | AD10: 13412258
A11: =D11&"_"&C11 -> Total Aircraft Movements_Vietnam | B11: Asia-Pacific | C11: Vietnam | D11: Total Aircraft Movements | E11: 449101 | F11: 508739.27 | G11: 583506.22 | H11: 659298.25 | I11: 739491.82 | J11: 825966.72 | K11: 917745.03 | L11: 1014576.5 | M11: 1116583.4 | N11: 1224065.9 | O11: 1339972.4 | P11: 1450667.8 | Q11: 1567566.6 | R11: 1691887.3 | S11: 1824315.2 | T11: 1965331.5 | U11: 2115294.3 | V11: 2268919.5 | W11: 2431674 | X11: 2604023.8 | Y11: 2786377.9 | Z11: 2979151.1 | AA11: 3169652.9 | AB11: 3370202.2 | AC11: 3581192.8 | AD11: 3803009.7
A12: =D12&"_"&C12 -> Total Passengers_United States | B12: North America | C12: United States | D12: Total Passengers | E12: 1590694448 | F12: 1682748982 | G12: 1778477380 | H12: 1857160818 | I12: 1925599883 | J12: 1980503494 | K12: 2034698235 | L12: 2088664348 | M12: 2141934605 | N12: 2194788772 | O12: 2247539254 | P12: 2300095595 | Q12: 2353903636 | R12: 2408903635 | S12: 2465141287 | T12: 2522736827 | U12: 2581211547 | V12: 2640656921 | W12: 2700897975 | X12: 2761653190 | Y12: 2822908476 | Z12: 2884557632 | AA12: 2947161722 | AB12: 3010556383 | AC12: 3074656111 | AD12: 3139850520
A13: =D13&"_"&C13 -> International Passengers_United States | B13: North America | C13: United States | D13: International Passengers | E13: 201404404 | F13: 215796097 | G13: 230925547 | H13: 249994798 | I13: 271085312 | J13: 293525642 | K13: 316499929 | L13: 340087686 | M13: 364050265 | N13: 388338990 | O13: 413183033 | P13: 438757900 | Q13: 465847717 | R13: 494384855 | S13: 524403223 | T13: 556053056 | U13: 589172798 | V13: 623800563 | W13: 659932473 | X13: 697392983 | Y13: 736149475 | Z13: 776215071 | AA13: 817924779 | AB13: 861275356 | AC13: 906328851 | AD13: 953486312
... A73: =D73&"_"&C73 -> International Passengers_Sri Lanka | B73: Asia-Pacific | C73: Sri Lanka | D73: International Passengers | E73: 7238597 | F73: 8215144 | G73: 8672581 | H73: 9218494 | I73: 9811428 | J73: 10474920 | K73: 11156151 | L73: 11856121 | M73: 12567367 | N73: 13252719 | O73: 13987256 | P73: 14769176 | Q73: 15520133 | R73: 16273765 | S73: 17024128 | T73: 17774803 | U73: 18519777 | V73: 19236440 | W73: 19936916 | X73: 20616973 | Y73: 21204902 | Z73: 21758397 | AA73: 22302177 | AB73: 22817806 | AC73: 23303697 | AD73: 23762595
A74: =D74&"_"&C74 -> Domestic Passengers_Sri Lanka | B74: Asia-Pacific | C74: Sri Lanka | D74: Domestic Passengers | E74: - | F74: - | G74: - | H74: - | I74: - | J74: - | K74: - | L74: - | M74: - | N74: - | O74: - | P74: - | Q74: - | R74: - | S74: - | T74: - | U74: - | V74: - | W74: - | X74: - | Y74: - | Z74: - | AA74: - | AB74: - | AC74: - | AD74: -
A75: =D75&"_"&C75 -> Total Cargo_Sri Lanka | B75: Asia-Pacific | C75: Sri Lanka | D75: Total Cargo | E75: 223624 | F75: 233801.61 | G75: 244913.32 | H75: 256423.58 | I75: 268464.5 | J75: 281279.78 | K75: 294853.69 | L75: 309070.87 | M75: 323943.61 | N75: 338936.33 | O75: 355372.1 | P75: 372543.33 | Q75: 389681.8 | R75: 407582.74 | S75: 426242.17 | T75: 445796.48 | U75: 466203.37 | V75: 486666.94 | W75: 507934.6 | X75: 530027.4 | Y75: 552972.56 | Z75: 576770.52 | AA75: 600512.47 | AB75: 625039.04 | AC75: 650357.53 | AD75: 676472.37
A76: =D76&"_"&C76 -> Total Aircraft Movements_Sri Lanka | B76: Asia-Pacific | C76: Sri Lanka | D76: Total Aircraft Movements | E76: 61538 | F76: 67421.426 | G76: 69482.286 | H76: 71548.94 | I76: 73555.732 | J76: 75450.885 | K76: 77277.206 | L76: 79049.804 | M76: 80708.799 | N76: 82043.741 | O76: 83546.814 | P76: 85219.792 | Q76: 86582.322 | R76: 87835.981 | S76: 88967.726 | T76: 89971.287 | U76: 90849.129 | V76: 91504.924 | W76: 92000.246 | X76: 92346.012 | Y76: 92199.634 | Z76: 91851.431 | AA76: 91411.822 | AB76: 90801.637 | AC76: 90036.754 | AD76: 89148.348
A77: =D77&"_"&C77 -> Total Passengers_Spain | B77: Europe | C77: Spain | D77: Total Passengers | E77: 206937709 | F77: 230285002 | G77: 251159813 | H77: 270649403 | I77: 289234805 | J77: 305188696 | K77: 320565204 | L77: 335727159 | M77: 350330682 | N77: 365624053 | O77: 379394128 | P77: 390537803 | Q77: 401593365 | R77: 412290697 | S77: 422306453 | T77: 431404573 | U77: 440028274 | V77: 448553542 | W77: 456541725 | X77: 464159811 | Y77: 471469116 | Z77: 478323031 | AA77: 484853219 | AB77: 490909386 | AC77: 496727714 | AD77: 502146334
A78: =D78&"_"&C78 -> International Passengers_Spain | B78: Europe | C78: Spain | D78: International Passengers | E78: 144394058 | F78: 158580045 | G78: 172801355 | H78: 188179932 | I78: 204000059 | J78: 215421818 | K78: 226439557 | L78: 237289436 | M78: 247729547 | N78: 258641668 | O78: 268474618 | P78: 276461339 | Q78: 284380239 | R78: 292040375 | S78: 299223758 | T78: 305747357 | U78: 311927071 | V78: 317992241 | W78: 323588438 | X78: 328903677 | Y78: 333981196 | Z78: 338720283 | AA78: 343208888 | AB78: 347336070 | AC78: 351258213 | AD78: 354848174
A79: =D79&"_"&C79 -> Domestic Passengers_Spain | B79: Europe | C79: Spain | D79: Domestic Passengers | E79: 62103796 | F79: 70966875 | G79: 77829180 | H79: 81587302 | I79: 83558510 | J79: 87431236 | K79: 91149757 | L79: 94822887 | M79: 98328250 | N79: 101965951 | O79: 105181491 | P79: 107695093 | Q79: 110143898 | R79: 112470010 | S79: 114631543 | T79: 116555771 | U79: 118364453 | V79: 120139893 | W79: 121775396 | X79: 123295433 | Y79: 124749988 | Z79: 126118588 | AA79: 127408601 | AB79: 128588085 | AC79: 129685978 | AD79: 130666871
A80: =D80&"_"&C80 -> Total Cargo_Spain | B80: Europe | C80: Spain | D80: Total Cargo | E80: 747457 | F80: 801680.17 | G80: 800064.3 | H80: 805957.38 | I80: 815904.94 | J80: 829991.18 | K80: 844028.25 | L80: 857066.86 | M80: 869469 | N80: 881377.6 | O80: 892400.8 | P80: 902544.67 | Q80: 912142.34 | R80: 920676.31 | S80: 928239.37 | T80: 935296.42 | U80: 942053.69 | V80: 948524.57 | W80: 954096.61 | X80: 958740.01 | Y80: 962207.13 | Z80: 964408.67 | AA80: 965346.39 | AB80: 964799.84 | AC80: 962957.96 | AD80: 959978.61
A81: =D81&"_"&C81 -> Total Aircraft Movements_Spain | B81: Europe | C81: Spain | D81: Total Aircraft Movements | E81: 1902694 | F81: 2056060 | G81: 2190050.3 | H81: 2330647.6 | I81: 2471008.2 | J81: 2601281.7 | K81: 2727709.3 | L81: 2852136.1 | M81: 2971153.8 | N81: 3093780.8 | O81: 3200926 | P81: 3284610.2 | Q81: 3366925.8 | R81: 3445635.4 | S81: 3517887 | T81: 3581951.8 | U81: 3639768.1 | V81: 3695427.7 | W81: 3745285.1 | X81: 3793022.1 | Y81: 3838450.1 | Z81: 3880812.1 | AA81: 3920417.5 | AB81: 3956594.1 | AC81: 3991065.3 | AD81: 4022285.4
A82: =D82&"_"&C82 -> Total Passengers_South Africa | B82: Africa | C82: South Africa | D82: Total Passengers | E82: 38078886 | F82: 40710528 | G82: 41945279 | H82: 43271431 | I82: 44776362 | J82: 46737002 | K82: 48659578 | L82: 50489712 | M82: 52149857 | N82: 53646163 | O82: 54549191 | P82: 55650482 | Q82: 56679003 | R82: 57700791 | S82: 58674376 | T82: 59585691 | U82: 60310593 | V82: 61013066 | W82: 61728125 | X82: 62418213 | Y82: 63091831 | Z82: 63644776 | AA82: 64282605 | AB82: 64979786 | AC82: 65698538 | AD82: 66461833
A83: =D83&"_"&C83 -> International Passengers_South Africa | B83: Africa | C83: South Africa | D83: International Passengers | E83: 11592085 | F83: 11850337 | G83: 11622428 | H83: 11989885 | I83: 12406880 | J83: 12950145 | K83: 13482862 | L83: 13989966 | M83: 14449968 | N83: 14864573 | O83: 15114788 | P83: 15419940 | Q83: 15704928 | R83: 15988051 | S83: 16257817 | T83: 16510330 | U83: 16711189 | V83: 16905834 | W83: 17103967 | X83: 17295180 | Y83: 17481830 | Z83: 17635043 | AA83: 17811776 | AB83: 18004955 | AC83: 18204111 | AD83: 18415608
A84: =D84&"_"&C84 -> Domestic Passengers_South Africa | B84: Africa | C84: South Africa | D84: Domestic Passengers | E84: 26378864 | F84: 28744795 | G84: 30203955 | H84: 31158890 | I84: 32242561 | J84: 33654379 | K84: 35038787 | L84: 36356630 | M84: 37552067 | N84: 38629527 | O84: 39279779 | P84: 40072797 | Q84: 40813414 | R84: 41549183 | S84: 42250242 | T84: 42906462 | U84: 43428449 | V84: 43934286 | W84: 44449186 | X84: 44946104 | Y84: 45431163 | Z84: 45829328 | AA84: 46288616 | AB84: 46790642 | AC84: 47308201 | AD84: 47857834
A85: =D85&"_"&C85 -> Total Cargo_South Africa | B85: Africa | C85: South Africa | D85: Total Cargo | E85: 328658 | F85: 331316.81 | G85: 353385.67 | H85: 387692.74 | I85: 428597.84 | J85: 471831.66 | K85: 518165.56 | L85: 564823.02 | M85: 608820.06 | N85: 648112.84 | O85: 680821.99 | P85: 710131.92 | Q85: 738010.04 | R85: 764857.92 | S85: 791261.35 | T85: 817628.47 | U85: 844175.1 | V85: 870612.3 | W85: 896581.36 | X85: 921737.11 | Y85: 945709.57 | Z85: 968362.18 | AA85: 989828.07 | AB85: 1010086.7 | AC85: 1030520.3 | AD85: 1052107.1
A86: =D86&"_"&C86 -> Total Aircraft Movements_South Africa | B86: Africa | C86: South Africa | D86: Total Aircraft Movements | E86: 588669 | F86: 591559.96 | G86: 598031.84 | H86: 603814.25 | I86: 611488.36 | J86: 619117.13 | K86: 626255.25 | L86: 632620.43 | M86: 637810.72 | N86: 641786.66 | O86: 637419.21 | P86: 638325.75 | Q86: 638917.75 | R86: 640576.55 | S86: 642145.14 | T86: 643187.85 | U86: 642880.89 | V86: 642705.18 | W86: 642603.02 | X86: 642493.83 | Y86: 642312.92 | Z86: 641218.5 | AA86: 640586.31 | AB86: 640152.32 | AC86: 639955.78 | AD86: 640185.47
... A88: =D88&"_"&C88 -> International Passengers_Singapore | B88: Asia-Pacific | C88: Singapore | D88: International Passengers | E88: 54836000 | F88: 58670122 | G88: 58631963 | H88: 59965185 | I88: 61971046 | J88: 64849485 | K88: 67814555 | L88: 70857097 | M88: 73825838 | N88: 76699769 | O88: 79382653 | P88: 82031853 | Q88: 84710385 | R88: 87407314 | S88: 90147702 | T88: 92960229 | U88: 95194506 | V88: 97454720 | W88: 99708280 | X88: 101953813 | Y88: 104250402 | Z88: 106491497 | AA88: 108753382 | AB88: 111019493 | AC88: 113323242 | AD88: 115683276
A89: =D89&"_"&C89 -> Domestic Passengers_Singapore | B89: Asia-Pacific | C89: Singapore | D89: Domestic Passengers | E89: - | F89: - | G89: - | H89: - | I89: - | J89: - | K89: - | L89: - | M89: - | N89: - | O89: - | P89: - | Q89: - | R89: - | S89: - | T89: - | U89: - | V89: - | W89: - | X89: - | Y89: - | Z89: - | AA89: - | AB89: - | AC89: - | AD89: -
A90: =D90&"_"&C90 -> Total Cargo_Singapore | B90: Asia-Pacific | C90: Singapore | D90: Total Cargo | E90: 1887000 | F90: 1887799 | G90: 1903068.9 | H90: 1925453.2 | I90: 1948057.9 | J90: 1981312.4 | K90: 2004442.5 | L90: 2030012.3 | M90: 2053458.2 | N90: 2075116.3 | O90: 2089911.7 | P90: 2100457.2 | Q90: 2110821 | R90: 2121507.3 | S90: 2133041.7 | T90: 2146261.9 | U90: 2170594.3 | V90: 2196472.4 | W90: 2223493.8 | X90: 2251282.3 | Y90: 2279458.5 | Z90: 2307512.1 | AA90: 2335661.7 | AB90: 2364634.9 | AC90: 2395196.5 | AD90: 2428163.3
A91: =D91&"_"&C91 -> Total Aircraft Movements_Singapore | B91: Asia-Pacific | C91: Singapore | D91: Total Aircraft Movements | E91: 351290 | F91: 360722.31 | G91: 360986.47 | H91: 366394.77 | I91: 374301.21 | J91: 384428.48 | K91: 394507.99 | L91: 404682.84 | M91: 414080.06 | N91: 422655.27 | O91: 430041.31 | P91: 437151.39 | Q91: 444294.57 | R91: 451380.36 | S91: 458578.81 | T91: 465868.58 | U91: 470153.25 | V91: 474412.31 | W91: 478464.59 | X91: 482421.69 | Y91: 486258.42 | Z91: 489564.45 | AA91: 492571.14 | AB91: 495239.53 | AC91: 497765.97 | AD91: 500278.47
A92: =D92&"_"&C92 -> Total Passengers_Serbia | B92: Europe | C92: Serbia | D92: Total Passengers | E92: 4815913 | F92: 4882878 | G92: 4984695 | H92: 5249009 | I92: 5611542 | J92: 6115100 | K92: 6566108 | L92: 7031273 | M92: 7518246 | N92: 8025590 | O92: 8512446 | P92: 9008961 | Q92: 9515467 | R92: 9952732 | S92: 10367512 | T92: 10759142 | U92: 11132883 | V92: 11518999 | W92: 12072091 | X92: 12468582 | Y92: 12835496 | Z92: 13171788 | AA92: 13488830 | AB92: 13708407 | AC92: 13894457 | AD92: 14053998
A93: =D93&"_"&C93 -> International Passengers_Serbia | B93: Europe | C93: Serbia | D93: International Passengers | E93: 4812156 | F93: 4879069 | G93: 4980807 | H93: 5244914 | I93: 5607164 | J93: 6110330 | K93: 6560986 | L93: 7025788 | M93: 7512381 | N93: 8019329 | O93: 8505805 | P93: 9001933 | Q93: 9508044 | R93: 9944967 | S93: 10359424 | T93: 10750748 | U93: 11124198 | V93: 11510013 | W93: 12062674 | X93: 12458855 | Y93: 12825483 | Z93: 13161513 | AA93: 13478308 | AB93: 13697712 | AC93: 13883618 | AD93: 14043034
A94: =D94&"_"&C94 -> Domestic Passengers_Serbia | B94: Europe | C94: Serbia | D94: Domestic Passengers | E94: - | F94: - | G94: - | H94: - | I94: - | J94: - | K94: - | L94: - | M94: - | N94: - | O94: - | P94: - | Q94: - | R94: - | S94: - | T94: - | U94: - | V94: - | W94: - | X94: - | Y94: - | Z94: - | AA94: - | AB94: - | AC94: - | AD94: -
A95: =D95&"_"&C95 -> Total Cargo_Serbia | B95: Europe | C95: Serbia | D95: Total Cargo | E95: 15393 | F95: 16668.673 | G95: 16651.329 | H95: 16805.158 | I95: 17050.08 | J95: 17387.612 | K95: 17722.916 | L95: 18037.118 | M95: 18337.09 | N95: 18628.135 | O95: 18896.736 | P95: 19141.815 | Q95: 19375.508 | R95: 19585.719 | S95: 19774.075 | T95: 19949.795 | U95: 20118.802 | V95: 20281.819 | W95: 20425.636 | X95: 20548.349 | Y95: 20645.62 | Z95: 20715.24 | AA95: 20757.074 | AB95: 20765.778 | AC95: 20746.083 | AD95: 20700.902
A96: =D96&"_"&C96 -> Total Aircraft Movements_Serbia | B96: Europe | C96: Serbia | D96: Total Aircraft Movements | E96: 64456 | F96: 62608.52 | G96: 62770.101 | H96: 65199.079 | I96: 68838.522 | J96: 74269.866 | K96: 79029.179 | L96: 83900.833 | M96: 88960.621 | N96: 94143.77 | O96: 98961.323 | P96: 103804.91 | Q96: 108694.34 | R96: 112733.85 | S96: 116469.61 | T96: 119906.53 | U96: 123054.55 | V96: 126273.11 | W96: 131230.34 | X96: 134480.91 | Y96: 137405.38 | Z96: 140016.37 | AA96: 142412.29 | AB96: 143797.92 | AC96: 144851.26 | AD96: 145639.91
A97: =D97&"_"&C97 -> Total Passengers_Senegal | B97: Africa | C97: Senegal | D97: Total Passengers | E97: 1949717 | F97: 1959904 | G97: 1928514 | H97: 1945998 | I97: 2000388 | J97: 2105333 | K97: 2222330 | L97: 2340098 | M97: 2460276 | N97: 2582147 | O97: 2680504 | P97: 2809349 | Q97: 2958227 | R97: 3094491 | S97: 3254526 | T97: 3402925 | U97: 3555659 | V97: 3721048 | W97: 3891748 | X97: 4067577 | Y97: 4246677 | Z97: 4424297 | AA97: 4620986 | AB97: 4827012 | AC97: 5038977 | AD97: 5257078
A98: =D98&"_"&C98 -> International Passengers_Senegal | B98: Africa | C98: Senegal | D98: International Passengers | E98: 1771948 | F98: 1775825 | G98: 1722906 | H98: 1724022 | I98: 1764161 | J98: 1857316 | K98: 1959737 | L98: 2059522 | M98: 2158317 | N98: 2256748 | O98: 2327012 | P98: 2424988 | Q98: 2535610 | R98: 2633993 | S98: 2749587 | T98: 2851587 | U98: 2952360 | V98: 3057297 | W98: 3165416 | X98: 3275386 | Y98: 3385893 | Z98: 3490349 | AA98: 3608215 | AB98: 3732252 | AC98: 3858776 | AD98: 3989293
A99: =D99&"_"&C99 -> Domestic Passengers_Senegal | B99: Africa | C99: Senegal | D99: Domestic Passengers | E99: - | F99: - | G99: - | H99: - | I99: - | J99: - | K99: - | L99: - | M99: - | N99: - | O99: - | P99: - | Q99: - | R99: - | S99: - | T99: - | U99: - | V99: - | W99: - | X99: - | Y99: - | Z99: - | AA99: - | AB99: - | AC99: - | AD99: -
A100: =D100&"_"&C100 -> Total Cargo_Senegal | B100: Africa | C100: Senegal | D100: Total Cargo | E100: 36018 | F100: 42724.49 | G100: 45473.44 | H100: 49192.88 | I100: 54122.608 | J100: 58644.539 | K100: 64402.759 | L100: 70522.638 | M100: 77094.862 | N100: 84244.84 | O100: 91829.825 | P100: 100549.61 | Q100: 110768.77 | R100: 120387.01 | S100: 131915.87 | T100: 143040.85 | U100: 155281.19 | V100: 167991.25 | W100: 180870.23 | X100: 194136.13 | Y100: 207604.33 | Z100: 221341.93 | AA100: 236032.86 | AB100: 250881.24 | AC100: 265803.41 | AD100: 280694.58
...

Sheet watf_2017
B1: Metric | C1: Region | D1: Entity | E1: Advanced economies | F1: Emerging and developing economies | G1: G7 | H1: Euro area | I1: European Union | J1: Emerging and Developing Asia | K1: ASEAN-5 | L1: Sub-Saharan Africa | M1: BRICS | N1: NEXT 11 | O1: MINT | P1: Emerging aviation markets | Q1: Major exporters of manufactured goods | R1: 2016 | S1: 2017 | T1: 2018 | U1: 2019 | V1: 2020 | W1: 2021 | X1: 2022 | Y1: 2023 | Z1: 2024 | AA1: 2025 | AB1: 2026 | AC1: 2027 | AD1: 2028 | AE1: 2029 | AF1: 2030 | AG1: 2031 | AH1: 2032 | AI1: 2033 | AJ1: 2034 | AK1: 2035 | AL1: 2036 | AM1: 2037 | AN1: 2038 | AO1: 2039 | AP1: 2040
A2: =B2&"_"&D2 -> Total passengers_Zambia | B2: Total passengers | C2: AFR | D2: Zambia | E2: - | F2: ✓ | G2: - | H2: - | I2: - | J2: - | K2: - | L2: ✓ | M2: - | N2: - | O2: - | P2: - | Q2: - | R2: 1622263 | S2: 1760296 | T2: 1816747 | U2: 1857616 | V2: 1907566 | W2: 1971527 | X2: 2058392 | Y2: 2133823 | Z2: 2217784 | AA2: 2316418 | AB2: 2410500 | AC2: 2510223 | AD2: 2624963 | AE2: 2742251 | AF2: 2870001 | AG2: 3019217 | AH2: 3170166 | AI2: 3316404 | AJ2: 3494931 | AK2: 3661295 | AL2: 3861705 | AM2: 4068781 | AN2: 4272826 | AO2: 4512037 | AP2: 4751339
A3: =B3&"_"&D3 -> International passengers_Zambia | B3: International passengers | C3: AFR | D3: Zambia | E3: - | F3: ✓ | G3: - | H3: - | I3: - | J3: - | K3: - | L3: ✓ | M3: - | N3: - | O3: - | P3: - | Q3: - | R3: 1129947 | S3: 1220109 | T3: 1232859 | U3: 1224078 | V3: 1218208 | W3: 1218523 | X3: 1235390 | Y3: 1242250 | Z3: 1255731 | AA3: 1281063 | AB3: 1303654 | AC3: 1331744 | AD3: 1372643 | AE3: 1417405 | AF3: 1472103 | AG3: 1544743 | AH3: 1620291 | AI3: 1694159 | AJ3: 1792820 | AK3: 1883971 | AL3: 2000457 | AM3: 2122359 | AN3: 2242196 | AO3: 2385777 | AP3: 2536045
A4: =B4&"_"&D4 -> Domestic passengers_Zambia | B4: Domestic passengers | C4: AFR | D4: Zambia | E4: - | F4: ✓ | G4: - | H4: - | I4: - | J4: - | K4: - | L4: ✓ | M4: - | N4: - | O4: - | P4: - | Q4: - | R4: 268190 | S4: 278459 | T4: 280988 | U4: 286164 | V4: 294614 | W4: 308522 | X4: 327057 | Y4: 343169 | Z4: 360982 | AA4: 382221 | AB4: 403055 | AC4: 426195 | AD4: 454391 | AE4: 484708 | AF4: 519465 | AG4: 562015 | AH4: 607901 | AI4: 655388 | AJ4: 715022 | AK4: 774580 | AL4: 847274 | AM4: 925433 | AN4: 1006581 | AO4: 1102817 | AP4: 1195810
A5: =B5&"_"&D5 -> Total Cargo_Zambia | B5: Total Cargo | C5: AFR | D5: Zambia | E5: - | F5: ✓ | G5: - | H5: - | I5: - | J5: - | K5: - | L5: ✓ | M5: - | N5: - | O5: - | P5: - | Q5: - | R5: 17585 | S5: 17649 | T5: 19012 | U5: 20349 | V5: 21750 | W5: 23160 | X5: 24689 | Y5: 26167 | Z5: 27706 | AA5: 29301 | AB5: 30884 | AC5: 32599 | AD5: 34253 | AE5: 35829 | AF5: 37753 | AG5: 39588 | AH5: 41631 | AI5: 43453 | AJ5: 45716 | AK5: 47821 | AL5: 50178 | AM5: 52700 | AN5: 54934 | AO5: 57708 | AP5: 60665
A6: =B6&"_"&D6 -> Total aircraft movements_Zambia | B6: Total aircraft movements | C6: AFR | D6: Zambia | E6: - | F6: ✓ | G6: - | H6: - | I6: - | J6: - | K6: - | L6: ✓ | M6: - | N6: - | O6: - | P6: - | Q6: - | R6: 58425 | S6: 57759 | T6: 58743 | U6: 59224 | V6: 59554 | W6: 59864 | X6: 60252 | Y6: 60681 | Z6: 61205 | AA6: 61769 | AB6: 62428 | AC6: 63128 | AD6: 63858 | AE6: 64644 | AF6: 65524 | AG6: 66499 | AH6: 67568 | AI6: 68707 | AJ6: 69914 | AK6: 71255 | AL6: 72621 | AM6: 74173 | AN6: 75714 | AO6: 77472 | AP6: 79251
A7: =B7&"_"&D7 -> Total passengers_World | B7: Total passengers | C7: - | D7: World | E7: - | F7: - | G7: - | H7: - | I7: - | J7: - | K7: - | L7: - | M7: - | N7: - | O7: - | P7: - | Q7: - | R7: 7689289881 | S7: 8202518098 | T7: 8721190598 | U7: 9227346948 | V7: 9707711074 | W7: 10163902708 | X7: 10677618307 | Y7: 11163493202 | Z7: 11660738675 | AA7: 12211954311 | AB7: 12732186909 | AC7: 13251305292 | AD7: 13823945727 | AE7: 14406903698 | AF7: 15057632922 | AG7: 15663391869 | AH7: 16348657008 | AI7: 16997561466 | AJ7: 17717617193 | AK7: 18388025245 | AL7: 19142394218 | AM7: 19926786504 | AN7: 20645892521 | AO7: 21452589699 | AP7: 22277003225
A8: =B8&"_"&D8 -> International passengers_World | B8: International passengers | C8: - | D8: World | E8: - | F8: - | G8: - | H8: - | I8: - | J8: - | K8: - | L8: - | M8: - | N8: - | O8: - | P8: - | Q8: - | R8: 3110029066 | S8: 3382982466 | T8: 3654176382 | U8: 3910582410 | V8: 4150731039 | W8: 4381445689 | X8: 4636346851 | Y8: 4882521773 | Z8: 5134594487 | AA8: 5418254185 | AB8: 5687992419 | AC8: 5960678955 | AD8: 6260846248 | AE8: 6561401623 | AF8: 6913349827 | AG8: 7232706254 | AH8: 7606906934 | AI8: 7954518043 | AJ8: 8357044479 | AK8: 8717953756 | AL8: 9141043007 | AM8: 9581574839 | AN8: 9979014840 | AO8: 10439433170 | AP8: 10913088919
A9: =B9&"_"&D9 -> Domestic passengers_World | B9: Domestic passengers | C9: - | D9: World | E9: - | F9: - | G9: - | H9: - | I9: - | J9: - | K9: - | L9: - | M9: - | N9: - | O9: - | P9: - | Q9: - | R9: 4493298332 | S9: 4736460951 | T9: 4986730325 | U9: 5239177685 | V9: 5481999615 | W9: 5709995473 | X9: 5971244165 | Y9: 6213296618 | Z9: 6460742829 | AA9: 6730495843 | AB9: 6983113476 | AC9: 7231597264 | AD9: 7506053414 | AE9: 7790372402 | AF9: 8091005435 | AG9: 8379197751 | AH9: 8691991880 | AI9: 8994956794 | AJ9: 9314101495 | AK9: 9625161413 | AL9: 9957949832 | AM9: 10303268302 | AN9: 10626343352 | AO9: 10973983900 | AP9: 11326057634
A10: =B10&"_"&D10 -> Total Cargo_World | B10: Total Cargo | C10: - | D10: World | E10: - | F10: - | G10: - | H10: - | I10: - | J10: - | K10: - | L10: - | M10: - | N10: - | O10: - | P10: - | Q10: - | R10: 110281254 | S10: 119468965 | T10: 127158001 | U10: 132697715 | V10: 137031639 | W10: 140048197 | X10: 143099232 | Y10: 146152729 | Z10: 149208904 | AA10: 152260570 | AB10: 155317617 | AC10: 158389263 | AD10: 161377844 | AE10: 164013591 | AF10: 167951546 | AG10: 170566673 | AH10: 174474530 | AI10: 177070120 | AJ10: 180949426 | AK10: 183526463 | AL10: 187378624 | AM10: 191215121 | AN10: 193764300 | AO10: 197575651 | AP10: 201372455
A11: =B11&"_"&D11 -> Total aircraft movements_World | B11: Total aircraft movements | C11: - | D11: World | E11: - | F11: - | G11: - | H11: - | I11: - | J11: - | K11: - | L11: - | M11: - | N11: - | O11: - | P11: - | Q11: - | R11: 91751269 | S11: 93855449 | T11: 96101464 | U11: 98340277 | V11: 100575368 | W11: 102755792 | X11: 104936217 | Y11: 107116641 | Z11: 109297066 | AA11: 111477490 | AB11: 113657915 | AC11: 115838339 | AD11: 118018763 | AE11: 120199188 | AF11: 122379612 | AG11: 124560037 | AH11: 126740461 | AI11: 128920886 | AJ11: 131101310 | AK11: 133281735 | AL11: 135462159 | AM11: 137642583 | AN11: 139823008 | AO11: 142003432 | AP11: 144183857
A12: =B12&"_"&D12 -> Total passengers_Vietnam | B12: Total passengers | C12: ASP | D12: Vietnam | E12: - | F12: ✓ | G12: - | H12: - | I12: - | J12: ✓ | K12: ✓ | L12: - | M12: - | N12: ✓ | O12: - | P12: ✓ | Q12: - | R12: 80942365 | S12: 96329678 | T12: 113979121 | U12: 130035580 | V12: 144885933 | W12: 158362702 | X12: 171667977 | Y12: 185205093 | Z12: 199440404 | AA12: 213706939 | AB12: 228425423 | AC12: 244548203 | AD12: 263141129 | AE12: 280829268 | AF12: 302707897 | AG12: 322421762 | AH12: 345861641 | AI12: 369237244 | AJ12: 393957658 | AK12: 418808116 | AL12: 446024553 | AM12: 474249359 | AN12: 502734283 | AO12: 533454506 | AP12: 567068950
A13: =B13&"_"&D13 -> International passengers_Vietnam | B13: International passengers | C13: ASP | D13: Vietnam | E13: - | F13: ✓ | G13: - | H13: - | I13: - | J13: ✓ | K13: ✓ | L13: - | M13: - | N13: ✓ | O13: - | P13: ✓ | Q13: - | R13: 23810517 | S13: 28298418 | T13: 32440828 | U13: 36286055 | V13: 40161281 | W13: 44782939 | X13: 48990050 | Y13: 53856360 | Z13: 59091143 | AA13: 64246614 | AB13: 70073137 | AC13: 76882488 | AD13: 85056699 | AE13: 92926618 | AF13: 103411271 | AG13: 112723217 | AH13: 124701824 | AI13: 136710802 | AJ13: 149952342 | AK13: 163994223 | AL13: 179494351 | AM13: 196217551 | AN13: 213902683 | AO13: 233415243 | AP13: 255132707
... A23: =B23&"_"&D23 -> International passengers_Uruguay | B23: International passengers | C23: LAC | D23: Uruguay | E23: - | F23: ✓ | G23: - | H23: - | I23: - | J23: - | K23: - | L23: - | M23: - | N23: - | O23: - | P23: - | Q23: - | R23: 2028473 | S23: 2172306 | T23: 2152059 | U23: 2194484 | V23: 2279674 | W23: 2387687 | X23: 2515842 | Y23: 2639899 | Z23: 2776018 | AA23: 2923375 | AB23: 3089769 | AC23: 3214829 | AD23: 3360245 | AE23: 3521716 | AF23: 3721643 | AG23: 3883867 | AH23: 4077021 | AI23: 4285360 | AJ23: 4471289 | AK23: 4707805 | AL23: 4912326 | AM23: 5163755 | AN23: 5414918 | AO23: 5627630 | AP23: 5884754
A24: =B24&"_"&D24 -> Domestic passengers_Uruguay | B24: Domestic passengers | C24: LAC | D24: Uruguay | E24: - | F24: ✓ | G24: - | H24: - | I24: - | J24: - | K24: - | L24: - | M24: - | N24: - | O24: - | P24: - | Q24: - | R24: - | S24: - | T24: - | U24: - | V24: - | W24: - | X24: - | Y24: - | Z24: - | AA24: - | AB24: - | AC24: - | AD24: - | AE24: - | AF24: - | AG24: - | AH24: - | AI24: - | AJ24: - | AK24: - | AL24: - | AM24: - | AN24: - | AO24: - | AP24: -
A25: =B25&"_"&D25 -> Total Cargo_Uruguay | B25: Total Cargo | C25: LAC | D25: Uruguay | E25: - | F25: ✓ | G25: - | H25: - | I25: - | J25: - | K25: - | L25: - | M25: - | N25: - | O25: - | P25: - | Q25: - | R25: 28992 | S25: 28054 | T25: 27954 | U25: 28188 | V25: 28670 | W25: 29239 | X25: 29848 | Y25: 30412 | Z25: 31079 | AA25: 31683 | AB25: 32566 | AC25: 33138 | AD25: 33698 | AE25: 34293 | AF25: 35299 | AG25: 35820 | AH25: 36686 | AI25: 37447 | AJ25: 38206 | AK25: 39088 | AL25: 39894 | AM25: 40920 | AN25: 41732 | AO25: 42561 | AP25: 43599
A26: =B26&"_"&D26 -> Total aircraft movements_Uruguay | B26: Total aircraft movements | C26: LAC | D26: Uruguay | E26: - | F26: ✓ | G26: - | H26: - | I26: - | J26: - | K26: - | L26: - | M26: - | N26: - | O26: - | P26: - | Q26: - | R26: 32619 | S26: 32463 | T26: 32915 | U26: 32968 | V26: 32976 | W26: 32898 | X26: 32819 | Y26: 32639 | Z26: 32681 | AA26: 32588 | AB26: 32733 | AC26: 32667 | AD26: 32659 | AE26: 32863 | AF26: 32838 | AG26: 32924 | AH26: 33003 | AI26: 33061 | AJ26: 33119 | AK26: 33326 | AL26: 33391 | AM26: 33408 | AN26: 33452 | AO26: 33629 | AP26: 33627
A27: =B27&"_"&D27 -> Total passengers_United Kingdom | B27: Total passengers | C27: EUR | D27: United Kingdom | E27: ✓ | F27: - | G27: ✓ | H27: - | I27: ✓ | J27: - | K27: - | L27: - | M27: - | N27: - | O27: - | P27: - | Q27: ✓ | R27: 272153051 | S27: 286576698 | T27: 291862494 | U27: 297934206 | V27: 305162462 | W27: 313895391 | X27: 325587627 | Y27: 336776939 | Z27: 344836017 | AA27: 356753484 | AB27: 366019461 | AC27: 375032168 | AD27: 383789540 | AE27: 396345476 | AF27: 407114944 | AG27: 415689726 | AH27: 427754891 | AI27: 437649750 | AJ27: 451802056 | AK27: 460805996 | AL27: 472672288 | AM27: 484195505 | AN27: 493159747 | AO27: 506056808 | AP27: 516282328
A28: =B28&"_"&D28 -> International passengers_United Kingdom | B28: International passengers | C28: EUR | D28: United Kingdom | E28: ✓ | F28: - | G28: ✓ | H28: - | I28: ✓ | J28: - | K28: - | L28: - | M28: - | N28: - | O28: - | P28: - | Q28: ✓ | R28: 226259500 | S28: 240338686 | T28: 246628196 | U28: 253152043 | V28: 260383342 | W28: 268564241 | X28: 279180290 | Y28: 289356060 | Z28: 296899227 | AA28: 307773350 | AB28: 316365278 | AC28: 324782883 | AD28: 332929471 | AE28: 344371020 | AF28: 354261163 | AG28: 362282282 | AH28: 373294492 | AI28: 382410254 | AJ28: 395246153 | AK28: 403625652 | AL28: 414465666 | AM28: 425009426 | AN28: 433310546 | AO28: 445073423 | AP28: 454495446
A29: =B29&"_"&D29 -> Domestic passengers_United Kingdom | B29: Domestic passengers | C29: EUR | D29: United Kingdom | E29: ✓ | F29: - | G29: ✓ | H29: - | I29: ✓ | J29: - | K29: - | L29: - | M29: - | N29: - | O29: - | P29: - | Q29: ✓ | R29: 45644056 | S29: 46043196 | T29: 45083034 | U29: 44665316 | V29: 44689287 | W29: 45262392 | X29: 46354931 | Y29: 47381097 | Z29: 47906708 | AA29: 48957471 | AB29: 49637171 | AC29: 50236560 | AD29: 50850584 | AE29: 51967407 | AF29: 52848562 | AG29: 53403590 | AH29: 54457563 | AI29: 55237415 | AJ29: 56554381 | AK29: 57179234 | AL29: 58205815 | AM29: 59185494 | AN29: 59848778 | AO29: 60983080 | AP29: 61786663
A30: =B30&"_"&D30 -> Total Cargo_United Kingdom | B30: Total Cargo | C30: EUR | D30: United Kingdom | E30: ✓ | F30: - | G30: ✓ | H30: - | I30: ✓ | J30: - | K30: - | L30: - | M30: - | N30: - | O30: - | P30: - | Q30: ✓ | R30: 2623742 | S30: 2830347 | T30: 2982829 | U30: 3087310 | V30: 3163562 | W30: 3221589 | X30: 3283271 | Y30: 3346706 | Z30: 3393321 | AA30: 3452935 | AB30: 3497931 | AC30: 3563797 | AD30: 3607203 | AE30: 3672291 | AF30: 3742787 | AG30: 3791010 | AH30: 3867072 | AI30: 3906680 | AJ30: 3996097 | AK30: 4044858 | AL30: 4116726 | AM30: 4182223 | AN30: 4219817 | AO30: 4294569 | AP30: 4352509
A31: =B31&"_"&D31 -> Total aircraft movements_United Kingdom | B31: Total aircraft movements | C31: EUR | D31: United Kingdom | E31: ✓ | F31: - | G31: ✓ | H31: - | I31: ✓ | J31: - | K31: - | L31: - | M31: - | N31: - | O31: - | P31: - | Q31: ✓ | R31: 3196583 | S31: 3277099 | T31: 3345620 | U31: 3422266 | V31: 3503135 | W31: 3593596 | X31: 3677508 | Y31: 3761773 | Z31: 3841353 | AA31: 3924296 | AB31: 4010674 | AC31: 4087897 | AD31: 4169047 | AE31: 4248665 | AF31: 4323652 | AG31: 4405152 | AH31: 4483823 | AI31: 4559813 | AJ31: 4639026 | AK31: 4719841 | AL31: 4795203 | AM31: 4870167 | AN31: 4946250 | AO31: 5023646 | AP31: 5096006
A32: =B32&"_"&D32 -> Total passengers_United Arab Emirates | B32: Total passengers | C32: MEA | D32: United Arab Emirates | E32: - | F32: ✓ | G32: - | H32: - | I32: - | J32: - | K32: - | L32: - | M32: - | N32: - | O32: - | P32: ✓ | Q32: - | R32: 120165076 | S32: 127491716 | T32: 138081256 | U32: 149389089 | V32: 160882926 | W32: 174675133 | X32: 188260285 | Y32: 203197975 | Z32: 217382880 | AA32: 234695199 | AB32: 252302790 | AC32: 268731865 | AD32: 289195390 | AE32: 307819679 | AF32: 330369241 | AG32: 350318769 | AH32: 375263920 | AI32: 396218431 | AJ32: 420617261 | AK32: 445433806 | AL32: 471712912 | AM32: 501461558 | AN32: 527861393 | AO32: 557539082 | AP32: 585418356
A33: =B33&"_"&D33 -> International passengers_United Arab Emirates | B33: International passengers | C33: MEA | D33: United Arab Emirates | E33: - | F33: ✓ | G33: - | H33: - | I33: - | J33: - | K33: - | L33: - | M33: - | N33: - | O33: - | P33: ✓ | Q33: - | R33: 119253009 | S33: 126587888 | T33: 137199471 | U33: 148538992 | V33: 160073151 | W33: 173912974 | X33: 187551464 | Y33: 202546516 | Z33: 216791090 | AA33: 234163744 | AB33: 251830852 | AC33: 268317354 | AD33: 288835190 | AE33: 307509909 | AF33: 330105510 | AG33: 350096406 | AH33: 375078184 | AI33: 396064674 | AJ33: 420491065 | AK33: 445331072 | AL33: 471629923 | AM33: 501395006 | AN33: 527808386 | AO33: 557497134 | AP33: 585385356
A34: =B34&"_"&D34 -> Domestic passengers_United Arab Emirates | B34: Domestic passengers | C34: MEA | D34: United Arab Emirates | E34: - | F34: ✓ | G34: - | H34: - | I34: - | J34: - | K34: - | L34: - | M34: - | N34: - | O34: - | P34: ✓ | Q34: - | R34: - | S34: - | T34: - | U34: - | V34: - | W34: - | X34: - | Y34: - | Z34: - | AA34: - | AB34: - | AC34: - | AD34: - | AE34: - | AF34: - | AG34: - | AH34: - | AI34: - | AJ34: - | AK34: - | AL34: - | AM34: - | AN34: - | AO34: - | AP34: -
A35: =B35&"_"&D35 -> Total Cargo_United Arab Emirates | B35: Total Cargo | C35: MEA | D35: United Arab Emirates | E35: - | F35: ✓ | G35: - | H35: - | I35: - | J35: - | K35: - | L35: - | M35: - | N35: - | O35: - | P35: ✓ | Q35: - | R35: 4459947 | S35: 4393590 | T35: 4456214 | U35: 4600989 | V35: 4788389 | W35: 5069441 | X35: 5329799 | Y35: 5624745 | Z35: 5901966 | AA35: 6201804 | AB35: 6522087 | AC35: 6806775 | AD35: 7127823 | AE35: 7401358 | AF35: 7771579 | AG35: 8059026 | AH35: 8445032 | AI35: 8728035 | AJ35: 9076563 | AK35: 9403326 | AL35: 9764011 | AM35: 10167805 | AN35: 10462423 | AO35: 10837711 | AP35: 11207530
A36: =B36&"_"&D36 -> Total aircraft movements_United Arab Emirates | B36: Total aircraft movements | C36: MEA | D36: United Arab Emirates | E36: - | F36: ✓ | G36: - | H36: - | I36: - | J36: - | K36: - | L36: - | M36: - | N36: - | O36: - | P36: ✓ | Q36: - | R36: 791691 | S36: 814269 | T36: 869186 | U36: 923310 | V36: 972428 | W36: 1013961 | X36: 1052708 | Y36: 1090550 | Z36: 1124836 | AA36: 1157839 | AB36: 1191521 | AC36: 1216334 | AD36: 1240189 | AE36: 1262429 | AF36: 1285752 | AG36: 1305934 | AH36: 1322777 | AI36: 1337169 | AJ36: 1352504 | AK36: 1365922 | AL36: 1379857 | AM36: 1392212 | AN36: 1401696 | AO36: 1411989 | AP36: 1421927
A37: =B37&"_"&D37 -> Total passengers_Ukraine | B37: Total passengers | C37: EUR | D37: Ukraine | E37: - | F37: ✓ | G37: - | H37: - | I37: - | J37: - | K37: - | L37: - | M37: - | N37: - | O37: - | P37: - | Q37: - | R37: 12845675 | S37: 15769945 | T37: 17820317 | U37: 19427526 | V37: 20873567 | W37: 21568048 | X37: 22904232 | Y37: 23683302 | Z37: 24440203 | AA37: 25598691 | AB37: 26548483 | AC37: 27848323 | AD37: 28559739 | AE37: 29578330 | AF37: 30458122 | AG37: 31276344 | AH37: 32090865 | AI37: 33229844 | AJ37: 34636933 | AK37: 35726625 | AL37: 36883640 | AM37: 38106945 | AN37: 38574139 | AO37: 39966822 | AP37: 41157584
A38: =B38&"_"&D38 -> International passengers_Ukraine | B38: International passengers | C38: EUR | D38: Ukraine | E38: - | F38: ✓ | G38: - | H38: - | I38: - | J38: - | K38: - | L38: - | M38: - | N38: - | O38: - | P38: - | Q38: - | R38: 10932737 | S38: 13692391 | T38: 15675869 | U38: 17199597 | V38: 18541457 | W38: 19174190 | X38: 20365948 | Y38: 21059229 | Z38: 21732870 | AA38: 22767523 | AB38: 23653655 | AC38: 24868945 | AD38: 25570925 | AE38: 26549819 | AF38: 27404151 | AG38: 28202918 | AH38: 28987523 | AI38: 30052704 | AJ38: 31356888 | AK38: 32371246 | AL38: 33443780 | AM38: 34583765 | AN38: 35047685 | AO38: 36347357 | AP38: 37464824
A39: =B39&"_"&D39 -> Domestic passengers_Ukraine | B39: Domestic passengers | C39: EUR | D39: Ukraine | E39: - | F39: ✓ | G39: - | H39: - | I39: - | J39: - | K39: - | L39: - | M39: - | N39: - | O39: - | P39: - | Q39: - | R39: 1492895 | S39: 1735279 | T39: 1867109 | U39: 2004359 | V39: 2152739 | W39: 2250587 | X39: 2424329 | Y39: 2533800 | Z39: 2636096 | AA39: 2775163 | AB39: 2850956 | AC39: 2945131 | AD39: 2962171 | AE39: 3007853 | AF39: 3038006 | AG39: 3061126 | AH39: 3093896 | AI39: 3169907 | AJ39: 3274524 | AK39: 3351178 | AL39: 3436673 | AM39: 3520769 | AN39: 3524637 | AO39: 3618099 | AP39: 3691737
A40: =B40&"_"&D40 -> Total Cargo_Ukraine | B40: Total Cargo | C40: EUR | D40: Ukraine | E40: - | F40: ✓ | G40: - | H40: - | I40: - | J40: - | K40: - | L40: - | M40: - | N40: - | O40: - | P40: - | Q40: - | R40: 38778 | S40: 47685 | T40: 50295 | U40: 52925 | V40: 55673 | W40: 57576 | X40: 60642 | Y40: 62660 | Z40: 64508 | AA40: 66787 | AB40: 68445 | AC40: 70894 | AD40: 71916 | AE40: 73405 | AF40: 74993 | AG40: 76126 | AH40: 77593 | AI40: 79319 | AJ40: 81973 | AK40: 83740 | AL40: 85927 | AM40: 88110 | AN40: 88630 | AO40: 91089 | AP40: 93202
A41: =B41&"_"&D41 -> Total aircraft movements_Ukraine | B41: Total aircraft movements | C41: EUR | D41: Ukraine | E41: - | F41: ✓ | G41: - | H41: - | I41: - | J41: - | K41: - | L41: - | M41: - | N41: - | O41: - | P41: - | Q41: - | R41: 122419 | S41: 142105 | T41: 146244 | U41: 152503 | V41: 159995 | W41: 167678 | X41: 176551 | Y41: 184309 | Z41: 192035 | AA41: 200140 | AB41: 207361 | AC41: 214337 | AD41: 220166 | AE41: 225988 | AF41: 231621 | AG41: 237661 | AH41: 243535 | AI41: 250939 | AJ41: 258603 | AK41: 266451 | AL41: 274080 | AM41: 281842 | AN41: 287989 | AO41: 296117 | AP41: 304061
A42: =B42&"_"&D42 -> Total passengers_Uganda | B42: Total passengers | C42: AFR | D42: Uganda | E42: - | F42: ✓ | G42: - | H42: - | I42: - | J42: - | K42: - | L42: - | M42: - | N42: - | O42: - | P42: - | Q42: - | R42: 1549549 | S42: 1661983 | T42: 1737268 | U42: 1822984 | V42: 1923521 | W42: 2042372 | X42: 2162016 | Y42: 2275335 | Z42: 2396043 | AA42: 2541506 | AB42: 2678948 | AC42: 2824430 | AD42: 2996347 | AE42: 3164528 | AF42: 3348483 | AG42: 3558702 | AH42: 3774976 | AI42: 3991454 | AJ42: 4250224 | AK42: 4498461 | AL42: 4791451 | AM42: 5095606 | AN42: 5401380 | AO42: 5756974 | AP42: 6086789
A43: =B43&"_"&D43 -> International passengers_Uganda | B43: International passengers | C43: AFR | D43: Uganda | E43: - | F43: ✓ | G43: - | H43: - | I43: - | J43: - | K43: - | L43: - | M43: - | N43: - | O43: - | P43: - | Q43: - | R43: 1401579 | S43: 1492993 | T43: 1546001 | U43: 1608465 | V43: 1685118 | W43: 1779843 | X43: 1875540 | Y43: 1965533 | Z43: 2063967 | AA43: 2188613 | AB43: 2307060 | AC43: 2435672 | AD43: 2593082 | AE43: 2749282 | AF43: 2923871 | AG43: 3127357 | AH43: 3339485 | AI43: 3554302 | AJ43: 3813753 | AK43: 4064832 | AL43: 4362623 | AM43: 4673321 | AN43: 4987157 | AO43: 5352113 | AP43: 5692376
A44: =B44&"_"&D44 -> Domestic passengers_Uganda | B44: Domestic passengers | C44: AFR | D44: Uganda | E44: - | F44: ✓ | G44: - | H44: - | I44: - | J44: - | K44: - | L44: - | M44: - | N44: - | O44: - | P44: - | Q44: - | R44: - | S44: - | T44: - | U44: - | V44: - | W44: - | X44: - | Y44: - | Z44: - | AA44: - | AB44: - | AC44: - | AD44: - | AE44: - | AF44: - | AG44: - | AH44: - | AI44: - | AJ44: - | AK44: - | AL44: - | AM44: - | AN44: - | AO44: - | AP44: -
A45: =B45&"_"&D45 -> Total Cargo_Uganda | B45: Total Cargo | C45: AFR | D45: Uganda | E45: - | F45: ✓ | G45: - | H45: - | I45: - | J45: - | K45: - | L45: - | M45: - | N45: - | O45: - | P45: - | Q45: - | R45: 59544 | S45: 70880 | T45: 76235 | U45: 79285 | V45: 81239 | W45: 82273 | X45: 83914 | Y45: 85286 | Z45: 86765 | AA45: 88227 | AB45: 89608 | AC45: 91295 | AD45: 92717 | AE45: 93926 | AF45: 95966 | AG45: 97688 | AH45: 99893 | AI45: 101519 | AJ45: 104129 | AK45: 106321 | AL45: 108992 | AM45: 111932 | AN45: 114213 | AO45: 117570 | AP45: 119873
A46: =B46&"_"&D46 -> Total aircraft movements_Uganda | B46: Total aircraft movements | C46: AFR | D46: Uganda | E46: - | F46: ✓ | G46: - | H46: - | I46: - | J46: - | K46: - | L46: - | M46: - | N46: - | O46: - | P46: - | Q46: - | R46: 42099 | S46: 43964 | T46: 45213 | U46: 46160 | V46: 46965 | W46: 47591 | X46: 48206 | Y46: 48828 | Z46: 49475 | AA46: 50107 | AB46: 50756 | AC46: 51366 | AD46: 51959 | AE46: 52529 | AF46: 53131 | AG46: 53698 | AH46: 54278 | AI46: 54839 | AJ46: 55372 | AK46: 55923 | AL46: 56403 | AM46: 56949 | AN46: 57394 | AO46: 57907 | AP46: 58402
A47: =B47&"_"&D47 -> Total passengers_Turkey | B47: Total passengers | C47: EUR | D47: Turkey | E47: - | F47: ✓ | G47: - | H47: - | I47: - | J47: - | K47: - | L47: - | M47: - | N47: ✓ | O47: ✓ | P47: ✓ | Q47: - | R47: 174037105 | S47: 183994386 | T47: 194580245 | U47: 204436736 | V47: 213749578 | W47: 221532698 | X47: 230611767 | Y47: 239644101 | Z47: 247729998 | AA47: 258857318 | AB47: 268146822 | AC47: 278297508 | AD47: 287158999 | AE47: 298848383 | AF47: 309180419 | AG47: 318324945 | AH47: 329185378 | AI47: 338402278 | AJ47: 350884831 | AK47: 360436521 | AL47: 371026904 | AM47: 381352347 | AN47: 389593649 | AO47: 400858485 | AP47: 409865457
A48: =B48&"_"&D48 -> International passengers_Turkey | B48: International passengers | C48: EUR | D48: Turkey | E48: - | F48: ✓ | G48: - | H48: - | I48: - | J48: - | K48: - | L48: - | M48: - | N48: ✓ | O48: ✓ | P48: ✓ | Q48: - | R48: 71212541 | S48: 78550295 | T48: 81031127 | U48: 84484113 | V48: 88492672 | W48: 92722342 | X48: 97717511 | Y48: 102928793 | Z48: 107943612 | AA48: 114486457 | AB48: 120371784 | AC48: 126765879 | AD48: 132671685 | AE48: 139989625 | AF48: 146777739 | AG48: 152946827 | AH48: 160060587 | AI48: 166462420 | AJ48: 174548593 | AK48: 181237416 | AL48: 188508878 | AM48: 195716489 | AN48: 201895120 | AO48: 209679202 | AP48: 216308044
A49: =B49&"_"&D49 -> Domestic passengers_Turkey | B49: Domestic passengers | C49: EUR | D49: Turkey | E49: - | F49: ✓ | G49: - | H49: - | I49: - | J49: - | K49: - | L49: - | M49: - | N49: ✓ | O49: ✓ | P49: ✓ | Q49: - | R49: 102418441 | S49: 105135345 | T49: 113315721 | U49: 119777090 | V49: 125125517 | W49: 128712447 | X49: 132821603 | Y49: 136661611 | Z49: 139746853 | AA49: 144341865 | AB49: 147753847 | AC49: 151516196 | AD49: 154476114 | AE49: 158850655 | AF49: 162396837 | AG49: 165373919 | AH49: 169121782 | AI49: 171937709 | AJ49: 176334708 | AK49: 179198018 | AL49: 182517257 | AM49: 185635315 | AN49: 187698147 | AO49: 191179016 | AP49: 193557225
...

Sheet watf_2018
B1: Metric | C1: Region | D1: Entity | E1: Advanced economies | F1: Emerging and developing economies | G1: G7 | H1: Euro area | I1: European union | J1: Emerging and developing Asia | K1: ASEAN-5 | L1: Sub-Saharan Africa | M1: BRICS | N1: NEXT 11 | O1: MINT | P1: Emerging aviation markets | Q1: Major exporters of manufactured goods | R1: 2017 | S1: 2018 | T1: 2019 | U1: 2020 | V1: 2021 | W1: 2022 | X1: 2023 | Y1: 2024 | Z1: 2025 | AA1: 2026 | AB1: 2027 | AC1: 2028 | AD1: 2029 | AE1: 2030 | AF1: 2031 | AG1: 2032 | AH1: 2033 | AI1: 2034 | AJ1: 2035 | AK1: 2036 | AL1: 2037 | AM1: 2038 | AN1: 2039 | AO1: 2040
A2: =B2&"_"&D2 -> Total passengers_United States | B2: Total passengers | C2: NAM | D2: United States | E2: ✓ | F2: - | G2: ✓ | H2: - | I2: - | J2: - | K2: - | L2: - | M2: - | N2: - | O2: - | P2: - | Q2: ✓ | R2: 1708538159 | S2: 1.7967635e+09 | T2: 1.8805222e+09 | U2: 1.9423873e+09 | V2: 1.9926801e+09 | W2: 2.0277259e+09 | X2: 2.0744887e+09 | Y2: 2.111097e+09 | Z2: 2.1595178e+09 | AA2: 2.2088361e+09 | AB2: 2.2591573e+09 | AC2: 2.310558e+09 | AD2: 2.3631349e+09 | AE2: 2.4169685e+09 | AF2: 2.4721504e+09 | AG2: 2.5396777e+09 | AH2: 2.5977883e+09 | AI2: 2.6684464e+09 | AJ2: 2.7298197e+09 | AK2: 2.8039318e+09 | AL2: 2.8799151e+09 | AM2: 2.9578464e+09 | AN2: 3.0267817e+09 | AO2: 3.1088827e+09
A3: =B3&"_"&D3 -> Total aircraft movements_United States | B3: Total aircraft movements | C3: NAM | D3: United States | E3: ✓ | F3: - | G3: ✓ | H3: - | I3: - | J3: - | K3: - | L3: - | M3: - | N3: - | O3: - | P3: - | Q3: ✓ | R3: 28708505 | S3: 29222963 | T3: 29520556 | U3: 29646947 | V3: 29740555 | W3: 29817126 | X3: 29893696 | Y3: 29970266 | Z3: 30046836 | AA3: 30123406 | AB3: 30199977 | AC3: 30276547 | AD3: 30353117 | AE3: 30429687 | AF3: 30506258 | AG3: 30582828 | AH3: 30659398 | AI3: 30735968 | AJ3: 30812538 | AK3: 30889109 | AL3: 30965679 | AM3: 31042249 | AN3: 31118819 | AO3: 31195389
A4: =B4&"_"&D4 -> Total Cargo_United States | B4: Total Cargo | C4: NAM | D4: United States | E4: ✓ | F4: - | G4: ✓ | H4: - | I4: - | J4: - | K4: - | L4: - | M4: - | N4: - | O4: - | P4: - | Q4: ✓ | R4: 31740500 | S4: 33352146 | T4: 34937714 | U4: 36173193 | V4: 36928543 | W4: 37000490 | X4: 37188437 | Y4: 37255668 | Z4: 37437218 | AA4: 37615265 | AB4: 37791095 | AC4: 37965287 | AD4: 38138802 | AE4: 38312161 | AF4: 38486059 | AG4: 38771862 | AH4: 38947160 | AI4: 39235164 | AJ4: 39413074 | AK4: 39703984 | AL4: 39996837 | AM4: 40291421 | AN4: 40475513 | AO4: 40773480
A5: =B5&"_"&D5 -> International passengers_United States | B5: International passengers | C5: NAM | D5: United States | E5: ✓ | F5: - | G5: ✓ | H5: - | I5: - | J5: - | K5: - | L5: - | M5: - | N5: - | O5: - | P5: - | Q5: ✓ | R5: 224572484 | S5: 235615627 | T5: 246658770 | U5: 2.5848527e+08 | V5: 2.7153441e+08 | W5: 2.8627831e+08 | X5: 3.0182275e+08 | Y5: 3.1821122e+08 | Z5: 3.3548954e+08 | AA5: 3.5370602e+08 | AB5: 3.729116e+08 | AC5: 3.9315998e+08 | AD5: 4.145078e+08 | AE5: 4.3701473e+08 | AF5: 4.6074372e+08 | AG5: 4.8576112e+08 | AH5: 5.1213688e+08 | AI5: 5.3994476e+08 | AJ5: 5.6926251e+08 | AK5: 6.0017212e+08 | AL5: 6.3276001e+08 | AM5: 6.6711731e+08 | AN5: 7.0334008e+08 | AO5: 7.4152962e+08
A6: =B6&"_"&D6 -> Domestic passengers_United States | B6: Domestic passengers | C6: NAM | D6: United States | E6: ✓ | F6: - | G6: ✓ | H6: - | I6: - | J6: - | K6: - | L6: - | M6: - | N6: - | O6: - | P6: - | Q6: ✓ | R6: 1480458680 | S6: 1.5569801e+09 | T6: 1.6293283e+09 | U6: 1.6793187e+09 | V6: 1.7165214e+09 | W6: 1.7367669e+09 | X6: 1.7679275e+09 | Y6: 1.7880883e+09 | Z6: 1.8191703e+09 | AA6: 1.8502104e+09 | AB6: 1.8812629e+09 | AC6: 1.9123505e+09 | AD6: 1.9435135e+09 | AE6: 1.9747725e+09 | AF6: 2.0061562e+09 | AG6: 2.0485954e+09 | AH6: 2.0802577e+09 | AI6: 2.1230339e+09 | AJ6: 2.1550137e+09 | AK6: 2.1981387e+09 | AL6: 2.2414548e+09 | AM6: 2.2849478e+09 | AN6: 2.3175774e+09 | AO6: 2.361404e+09
A7: =B7&"_"&D7 -> Total passengers_Canada | B7: Total passengers | C7: NAM | D7: Canada | E7: ✓ | F7: - | G7: ✓ | H7: - | I7: - | J7: - | K7: - | L7: - | M7: - | N7: - | O7: - | P7: - | Q7: ✓ | R7: 147324413 | S7: 1.5505551e+08 | T7: 1.6354876e+08 | U7: 1.699948e+08 | V7: 1.7624604e+08 | W7: 1.8234338e+08 | X7: 1.8842558e+08 | Y7: 1.9448874e+08 | Z7: 2.0054088e+08 | AA7: 2.0660832e+08 | AB7: 2.1269437e+08 | AC7: 2.1879011e+08 | AD7: 2.2489511e+08 | AE7: 2.309687e+08 | AF7: 2.3694636e+08 | AG7: 2.4292029e+08 | AH7: 2.4890653e+08 | AI7: 2.5490818e+08 | AJ7: 2.6090107e+08 | AK7: 2.6683949e+08 | AL7: 2.7277022e+08 | AM7: 2.7869464e+08 | AN7: 2.8462853e+08 | AO7: 2.9057327e+08
A8: =B8&"_"&D8 -> Total aircraft movements_Canada | B8: Total aircraft movements | C8: NAM | D8: Canada | E8: ✓ | F8: - | G8: ✓ | H8: - | I8: - | J8: - | K8: - | L8: - | M8: - | N8: - | O8: - | P8: - | Q8: ✓ | R8: 3096427 | S8: 3206319.5 | T8: 3279307.4 | U8: 3330942.8 | V8: 3363482.1 | W8: 3378622.2 | X8: 3394920.1 | Y8: 3412191.1 | Z8: 3430063 | AA8: 3448009.4 | AB8: 3465800.5 | AC8: 3483372.7 | AD8: 3500583.7 | AE8: 3517815 | AF8: 3535754.8 | AG8: 3553242.4 | AH8: 3570066.6 | AI8: 3586186.3 | AJ8: 3601921.7 | AK8: 3617847.1 | AL8: 3633435 | AM8: 3648739.6 | AN8: 3663600.2 | AO8: 3678048.8
A9: =B9&"_"&D9 -> Total Cargo_Canada | B9: Total Cargo | C9: NAM | D9: Canada | E9: ✓ | F9: - | G9: ✓ | H9: - | I9: - | J9: - | K9: - | L9: - | M9: - | N9: - | O9: - | P9: - | Q9: ✓ | R9: 1317644 | S9: 1373475 | T9: 1400441 | U9: 1416526 | V9: 1438046 | W9: 1439593 | X9: 1445172 | Y9: 1467427 | Z9: 1472089 | AA9: 1475738 | AB9: 1496328 | AC9: 1498356 | AD9: 1498214 | AE9: 1510043 | AF9: 1515722 | AG9: 1546631 | AH9: 1551079 | AI9: 1567126 | AJ9: 1582537 | AK9: 1600106 | AL9: 1613841 | AM9: 1619724 | AN9: 1651411 | AO9: 1664686
A10: =B10&"_"&D10 -> International passengers_Canada | B10: International passengers | C10: NAM | D10: Canada | E10: ✓ | F10: - | G10: ✓ | H10: - | I10: - | J10: - | K10: - | L10: - | M10: - | N10: - | O10: - | P10: - | Q10: ✓ | R10: 63797532 | S10: 68759178 | T10: 73258857 | U10: 76116307 | V10: 79277819 | W10: 83032273 | X10: 86786727 | Y10: 90541182 | Z10: 94295636 | AA10: 98050090 | AB10: 1.0180454e+08 | AC10: 1.05559e+08 | AD10: 1.0931345e+08 | AE10: 1.1306791e+08 | AF10: 1.1682236e+08 | AG10: 1.2057682e+08 | AH10: 1.2433127e+08 | AI10: 1.2808572e+08 | AJ10: 1.3184018e+08 | AK10: 1.3559463e+08 | AL10: 1.3934909e+08 | AM10: 1.4310354e+08 | AN10: 1.4685799e+08 | AO10: 1.5061245e+08
A11: =B11&"_"&D11 -> Domestic passengers_Canada | B11: Domestic passengers | C11: NAM | D11: Canada | E11: ✓ | F11: - | G11: ✓ | H11: - | I11: - | J11: - | K11: - | L11: - | M11: - | N11: - | O11: - | P11: - | Q11: ✓ | R11: 81114831 | S11: 84197715 | T11: 88321821 | U11: 91983765 | V11: 95110899 | W11: 97453783 | X11: 99781536 | Y11: 1.0209024e+08 | Z11: 1.0438793e+08 | AA11: 1.0670091e+08 | AB11: 1.0903251e+08 | AC11: 1.113738e+08 | AD11: 1.1372433e+08 | AE11: 1.1604347e+08 | AF11: 1.1826668e+08 | AG11: 1.2048616e+08 | AH11: 1.2271794e+08 | AI11: 1.2496513e+08 | AJ11: 1.2720357e+08 | AK11: 1.2938754e+08 | AL11: 1.3156381e+08 | AM11: 1.3373378e+08 | AN11: 1.3591321e+08 | AO11: 1.381035e+08
A12: =B12&"_"&D12 -> Total passengers_United Arab Emirates | B12: Total passengers | C12: MEA | D12: United Arab Emirates | E12: - | F12: ✓ | G12: - | H12: - | I12: - | J12: - | K12: - | L12: - | M12: - | N12: - | O12: - | P12: ✓ | Q12: - | R12: 124438787 | S12: 1.2110729e+08 | T12: 1.2856592e+08 | U12: 1.3735089e+08 | V12: 1.4755758e+08 | W12: 1.5909846e+08 | X12: 1.7112672e+08 | Y12: 1.8363815e+08 | Z12: 1.9662871e+08 | AA12: 2.1009158e+08 | AB12: 2.2402075e+08 | AC12: 2.3840902e+08 | AD12: 2.5324791e+08 | AE12: 2.6852809e+08 | AF12: 2.8423998e+08 | AG12: 3.0037396e+08 | AH12: 3.1691902e+08 | AI12: 3.3386366e+08 | AJ12: 3.5119575e+08 | AK12: 3.689032e+08 | AL12: 3.8697436e+08 | AM12: 4.0539531e+08 | AN12: 4.2415295e+08 | AO12: 4.4323388e+08
A13: =B13&"_"&D13 -> Total aircraft movements_United Arab Emirates | B13: Total aircraft movements | C13: MEA | D13: United Arab Emirates | E13: - | F13: ✓ | G13: - | H13: - | I13: - | J13: - | K13: - | L13: - | M13: - | N13: - | O13: - | P13: ✓ | Q13: - | R13: 779146 | S13: 751261.22 | T13: 752728.7 | U13: 764091.92 | V13: 784647.02 | W13: 814476.41 | X13: 844305.8 | Y13: 874135.19 | Z13: 903964.58 | AA13: 933793.96 | AB13: 963623.35 | AC13: 993452.74 | AD13: 1023282.1 | AE13: 1053111.5 | AF13: 1082940.9 | AG13: 1112770.3 | AH13: 1142599.7 | AI13: 1172429.1 | AJ13: 1202258.5 | AK13: 1232087.8 | AL13: 1261917.2 | AM13: 1291746.6 | AN13: 1321576 | AO13: 1351405.4
... A15: =B15&"_"&D15 -> International passengers_United Arab Emirates | B15: International passengers | C15: MEA | D15: United Arab Emirates | E15: - | F15: ✓ | G15: - | H15: - | I15: - | J15: - | K15: - | L15: - | M15: - | N15: - | O15: - | P15: ✓ | Q15: - | R15: 123705816 | S15: 1.2064332e+08 | T15: 1.2811659e+08 | U15: 1.3695885e+08 | V15: 1.471946e+08 | W15: 1.5875891e+08 | X15: 1.7081034e+08 | Y15: 1.8334483e+08 | Z15: 1.9635737e+08 | AA15: 2.0984207e+08 | AB15: 2.2379216e+08 | AC15: 2.3820009e+08 | AD15: 2.5305755e+08 | AE15: 2.6835555e+08 | AF15: 2.8408442e+08 | AG15: 3.0023391e+08 | AH15: 3.1679322e+08 | AI15: 3.3375103e+08 | AJ15: 3.5109558e+08 | AK15: 3.6881469e+08 | AL15: 3.8689582e+08 | AM15: 4.0532612e+08 | AN15: 4.2409245e+08 | AO15: 4.4318145e+08
A16: =B16&"_"&D16 -> Domestic passengers_United Arab Emirates | B16: Domestic passengers | C16: MEA | D16: United Arab Emirates | E16: - | F16: ✓ | G16: - | H16: - | I16: - | J16: - | K16: - | L16: - | M16: - | N16: - | O16: - | P16: ✓ | Q16: -
A17: =B17&"_"&D17 -> Total passengers_Saudi Arabia | B17: Total passengers | C17: MEA | D17: Saudi Arabia | E17: - | F17: ✓ | G17: - | H17: - | I17: - | J17: - | K17: - | L17: - | M17: - | N17: - | O17: - | P17: ✓ | Q17: - | R17: 91724973 | S17: 99807157 | T17: 1.0748841e+08 | U17: 1.1579002e+08 | V17: 1.23557e+08 | W17: 1.3130637e+08 | X17: 1.3915883e+08 | Y17: 1.4750942e+08 | Z17: 1.561275e+08 | AA17: 1.6524033e+08 | AB17: 1.7475375e+08 | AC17: 1.8480976e+08 | AD17: 1.953881e+08 | AE17: 2.0658875e+08 | AF17: 2.1844289e+08 | AG17: 2.3103385e+08 | AH17: 2.4441541e+08 | AI17: 2.5867843e+08 | AJ17: 2.7389786e+08 | AK17: 2.9017834e+08 | AL17: 3.0760717e+08 | AM17: 3.2630444e+08 | AN17: 3.4639062e+08 | AO17: 3.6800253e+08
A18: =B18&"_"&D18 -> Total aircraft movements_Saudi Arabia | B18: Total aircraft movements | C18: MEA | D18: Saudi Arabia | E18: - | F18: ✓ | G18: - | H18: - | I18: - | J18: - | K18: - | L18: - | M18: - | N18: - | O18: - | P18: ✓ | Q18: - | R18: 742725 | S18: 780316.51 | T18: 818866.47 | U18: 854088.66 | V18: 882017.97 | W18: 904916.93 | X18: 927691 | Y18: 950308.47 | Z18: 973266.75 | AA18: 992749.33 | AB18: 1012325.7 | AC18: 1031833.7 | AD18: 1051302.1 | AE18: 1071066 | AF18: 1087086.2 | AG18: 1103215.4 | AH18: 1119284.6 | AI18: 1135236.4 | AJ18: 1151127.9 | AK18: 1163068.8 | AL18: 1175514.9 | AM18: 1187929.6 | AN18: 1200292.4 | AO18: 1212545
A19: =B19&"_"&D19 -> Total Cargo_Saudi Arabia | B19: Total Cargo | C19: MEA | D19: Saudi Arabia | E19: - | F19: ✓ | G19: - | H19: - | I19: - | J19: - | K19: - | L19: - | M19: - | N19: - | O19: - | P19: ✓ | Q19: - | R19: 937518 | S19: 950467.17 | T19: 986086.96 | U19: 1029397.6 | V19: 1088597.6 | W19: 1152507.3 | X19: 1224536 | Y19: 1293331.2 | Z19: 1367715.8 | AA19: 1449116 | AB19: 1523395.7 | AC19: 1606550.3 | AD19: 1679722.5 | AE19: 1775589.6 | AF19: 1853999.7 | AG19: 1955886.5 | AH19: 2034707.7 | AI19: 2129534.4 | AJ19: 2219994.2 | AK19: 2320337.3 | AL19: 2431851.6 | AM19: 2518080.3 | AN19: 2624444.9 | AO19: 2730317.8
A20: =B20&"_"&D20 -> International passengers_Saudi Arabia | B20: International passengers | C20: MEA | D20: Saudi Arabia | E20: - | F20: ✓ | G20: - | H20: - | I20: - | J20: - | K20: - | L20: - | M20: - | N20: - | O20: - | P20: ✓ | Q20: - | R20: 46128894 | S20: 50420943 | T20: 53911296 | U20: 58215251 | V20: 62370727 | W20: 67109692 | X20: 71953528 | Y20: 77296110 | Z20: 82910629 | AA20: 89020708 | AB20: 95532910 | AC20: 1.0258762e+08 | AD20: 1.1016467e+08 | AE20: 1.1836683e+08 | AF20: 1.2721725e+08 | AG20: 1.3680558e+08 | AH20: 1.4718406e+08 | AI20: 1.5844305e+08 | AJ20: 1.7065797e+08 | AK20: 1.8392853e+08 | AL20: 1.9835192e+08 | AM20: 2.1404348e+08 | AN20: 2.3112347e+08 | AO20: 2.4972828e+08
A21: =B21&"_"&D21 -> Domestic passengers_Saudi Arabia | B21: Domestic passengers | C21: MEA | D21: Saudi Arabia | E21: - | F21: ✓ | G21: - | H21: - | I21: - | J21: - | K21: - | L21: - | M21: - | N21: - | O21: - | P21: ✓ | Q21: - | R21: 44993268 | S21: 48713073 | T21: 52854456 | U21: 56821969 | V21: 60412627 | W21: 63414037 | X21: 66415447 | Y21: 69416857 | Z21: 72418268 | AA21: 75419678 | AB21: 78421088 | AC21: 81422498 | AD21: 84423908 | AE21: 87425318 | AF21: 90426728 | AG21: 93428138 | AH21: 96429548 | AI21: 99430958 | AJ21: 1.0243237e+08 | AK21: 1.0543378e+08 | AL21: 1.0843519e+08 | AM21: 1.114366e+08 | AN21: 1.1443801e+08 | AO21: 1.1743942e+08
A22: =B22&"_"&D22 -> Total passengers_Qatar | B22: Total passengers | C22: MEA | D22: Qatar | E22: - | F22: ✓ | G22: - | H22: - | I22: - | J22: - | K22: - | L22: - | M22: - | N22: - | O22: - | P22: ✓ | Q22: - | R22: 35270410 | S22: 35829852 | T22: 37930738 | U22: 40474843 | V22: 43853233 | W22: 47791600 | X22: 52114716 | Y22: 56285563 | Z22: 61309774 | AA22: 66460865 | AB22: 71347290 | AC22: 77353962 | AD22: 82921289 | AE22: 89600024 | AF22: 95629868 | AG22: 1.0308207e+08 | AH22: 1.094965e+08 | AI22: 1.1691978e+08 | AJ22: 1.2452234e+08 | AK22: 1.3259935e+08 | AL22: 1.4172361e+08 | AM22: 1.4997472e+08 | AN22: 1.5922914e+08 | AO22: 1.6804506e+08
A23: =B23&"_"&D23 -> Total aircraft movements_Qatar | B23: Total aircraft movements | C23: MEA | D23: Qatar | E23: - | F23: ✓ | G23: - | H23: - | I23: - | J23: - | K23: - | L23: - | M23: - | N23: - | O23: - | P23: ✓ | Q23: - | R23: 249389 | S23: 241497.38 | T23: 249972.72 | U23: 260738.55 | V23: 272759.31 | W23: 285750.98 | X23: 298742.65 | Y23: 311734.32 | Z23: 324725.99 | AA23: 337717.66 | AB23: 350709.33 | AC23: 363700.99 | AD23: 376692.66 | AE23: 389684.33 | AF23: 402676 | AG23: 415667.67 | AH23: 428659.34 | AI23: 441651.01 | AJ23: 454642.68 | AK23: 467634.35 | AL23: 480626.02 | AM23: 493617.69 | AN23: 506609.36 | AO23: 519601.02
A24: =B24&"_"&D24 -> Total Cargo_Qatar | B24: Total Cargo | C24: MEA | D24: Qatar | E24: - | F24: ✓ | G24: - | H24: - | I24: - | J24: - | K24: - | L24: - | M24: - | N24: - | O24: - | P24: ✓ | Q24: - | R24: 2020942 | S24: 2183097.5 | T24: 2294524.1 | U24: 2402643.7 | V24: 2527639.3 | W24: 2689229.4 | X24: 2856314.9 | Y24: 3033770.1 | Z24: 3216800.7 | AA24: 3410895.5 | AB24: 3616681.8 | AC24: 3834869.4 | AD24: 4066258 | AE24: 4307934.3 | AF24: 4563939.6 | AG24: 4870784.1 | AH24: 5113819.1 | AI24: 5364197.3 | AJ24: 5622086.7 | AK24: 5887595.9 | AL24: 6141713.3 | AM24: 6401572.5 | AN24: 6667207.1 | AO24: 6938476.4
